Workbook

Sheet Leia-me
A1: IGNIÇÃO v5.2: achados da revisão
A2: Revisão completa da versão 5.2 (Edição Narrativa Enxuta) feita em outubro de 2026, com a comparação contra a revisão da v5.0. Acompanha o documento IGNIÇÃO: revisão da nova versão. Linha é sempre a linha do arquivo .md do volume na v5.2, salvo na aba Pendências, que traz a linha antiga e a nova.
A4: Abas
A5: Achados: os 5.722 problemas marcados na leitura da v5.2, um por linha, em ordem de volume e linha. A coluna Efeito da edição marca o que parece ter nascido da própria reescrita (troca mecânica de pontuação, emenda de capítulos fundidos, numeração antiga, parágrafo de molde).
A6: Pendências v5.0: 1.078 linhas. São 1.051 itens da revisão anterior conferidos no texto novo (afirmações que a checagem reprovou, conselhos arriscados graves, uma amostra estratificada dos outros achados graves e os exemplos citados no mapa da v5.0), com o status na v5.2 e o trecho novo, mais 16 contagens do mapa anterior refeitas por script e as 11 recomendações do plano de correção anterior, com o grau de execução.
A7: Checagem: as 780 afirmações conferidas na web em 24 de outubro de 2026, com veredito, o que vale nessa data e a fonte, mais 3 que ficaram sem checar. São 740 que os revisores marcaram como suspeitas, das mais arriscadas para as menos, e 40 que a própria edição escreveu ao corrigir achados antigos (tema Afirmação nova da edição). Na nota, 'base' e IDs como r1-trib-003 ou r2v8-034 remetem à aba Checagem da planilha da revisão anterior.
A8: Moldes: os 176 parágrafos de desfecho gerados por fórmula, um por unidade, com a família do rótulo e o arquétipo.
A9: Remissões: as 490 remissões numéricas a capítulos ("ver o Capítulo 7", "Vol. 8, Cap. 10") julgadas contra a numeração nova, inclusive as escritas no plural ("Capítulos 4 e 7 do Vol. 8").
A10: Links e fases: os 50 links internos que não resolvem ou caem em título repetido e as menções a fase com número errado.
A11: Resumo: contagens por fórmula sobre as outras abas. Mudam sozinhas quando você atualiza o Status.
A13: Como usar
A14: A coluna Status (fundo amarelo) é a única feita para editar. Valores aceitos: Pendente, Em revisão, Corrigido, Descartado.
... A19: Categorias
A20: Código | B20: Grupo | C20: O que marca
A21: E1 | B21: Escrita | C21: Antítese "não é X, é Y"
A22: E2 | B22: Escrita | C22: Fragmento telegráfico
A23: E3 | B23: Escrita | C23: Adjetivo inflado ou intensificador
A24: E4 | B24: Escrita | C24: Metadiscurso, abertura enfática, rótulo
A25: E5 | B25: Escrita | C25: Pergunta retórica com resposta imediata
A26: E6 | B26: Escrita | C26: Clichê ou metáfora gasta
A27: E7 | B27: Escrita | C27: Anglicismo ou mistura founder/fundador
A28: E8 | B28: Escrita | C28: Glosa repetida entre parênteses
A29: E9 | B29: Escrita | C29: Erro gramatical ou frase corrompida
A30: E10 | B30: Escrita | C30: Repetição, redundância, enchimento
A31: E11 | B31: Escrita | C31: Registro inconsistente ou tom de coach
... A55: C7 | B55: Conteúdo | C55: Conselho arriscado sem ressalva

Sheet Resumo
A1: Resumo da revisão da v5.2
A2: Tudo nesta aba é fórmula sobre as outras abas.
A4: Achados da v5.2 por volume e gravidade
A5: Volume | B5: Alta | C5: Média | D5: Baixa | E5: Total | F5: Efeito da edição | G5: Corrigidos | H5: % corrigido
A6: 1 | B6: =COUNTIFS(Achados!$B$2:$B$5723,$A6,Achados!$G$2:$G$5723,"alta") -> 203 | C6: =COUNTIFS(Achados!$B$2:$B$5723,$A6,Achados!$G$2:$G$5723,"média") -> 311 | D6: =COUNTIFS(Achados!$B$2:$B$5723,$A6,Achados!$G$2:$G$5723,"baixa") -> 57 | E6: =SUM(B6:D6) -> 571 | F6: =COUNTIFS(Achados!$B$2:$B$5723,$A6,Achados!$M$2:$M$5723,"sim") -> 249 | G6: =COUNTIFS(Achados!$B$2:$B$5723,$A6,Achados!$S$2:$S$5723,"Corrigido") -> 571 | H6: =IF(E6=0,0,G6/E6) -> 1
A7: 2 | B7: =COUNTIFS(Achados!$B$2:$B$5723,$A7,Achados!$G$2:$G$5723,"alta") -> 86 | C7: =COUNTIFS(Achados!$B$2:$B$5723,$A7,Achados!$G$2:$G$5723,"média") -> 171 | D7: =COUNTIFS(Achados!$B$2:$B$5723,$A7,Achados!$G$2:$G$5723,"baixa") -> 90 | E7: =SUM(B7:D7) -> 347 | F7: =COUNTIFS(Achados!$B$2:$B$5723,$A7,Achados!$M$2:$M$5723,"sim") -> 106 | G7: =COUNTIFS(Achados!$B$2:$B$5723,$A7,Achados!$S$2:$S$5723,"Corrigido") -> 347 | H7: =IF(E7=0,0,G7/E7) -> 1
A8: 3 | B8: =COUNTIFS(Achados!$B$2:$B$5723,$A8,Achados!$G$2:$G$5723,"alta") -> 126 | C8: =COUNTIFS(Achados!$B$2:$B$5723,$A8,Achados!$G$2:$G$5723,"média") -> 201 | D8: =COUNTIFS(Achados!$B$2:$B$5723,$A8,Achados!$G$2:$G$5723,"baixa") -> 37 | E8: =SUM(B8:D8) -> 364 | F8: =COUNTIFS(Achados!$B$2:$B$5723,$A8,Achados!$M$2:$M$5723,"sim") -> 143 | G8: =COUNTIFS(Achados!$B$2:$B$5723,$A8,Achados!$S$2:$S$5723,"Corrigido") -> 364 | H8: =IF(E8=0,0,G8/E8) -> 1
A9: 4 | B9: =COUNTIFS(Achados!$B$2:$B$5723,$A9,Achados!$G$2:$G$5723,"alta") -> 131 | C9: =COUNTIFS(Achados!$B$2:$B$5723,$A9,Achados!$G$2:$G$5723,"média") -> 286 | D9: =COUNTIFS(Achados!$B$2:$B$5723,$A9,Achados!$G$2:$G$5723,"baixa") -> 40 | E9: =SUM(B9:D9) -> 457 | F9: =COUNTIFS(Achados!$B$2:$B$5723,$A9,Achados!$M$2:$M$5723,"sim") -> 189 | G9: =COUNTIFS(Achados!$B$2:$B$5723,$A9,Achados!$S$2:$S$5723,"Corrigido") -> 457 | H9: =IF(E9=0,0,G9/E9) -> 1
A10: 5 | B10: =COUNTIFS(Achados!$B$2:$B$5723,$A10,Achados!$G$2:$G$5723,"alta") -> 164 | C10: =COUNTIFS(Achados!$B$2:$B$5723,$A10,Achados!$G$2:$G$5723,"média") -> 278 | D10: =COUNTIFS(Achados!$B$2:$B$5723,$A10,Achados!$G$2:$G$5723,"baixa") -> 99 | E10: =SUM(B10:D10) -> 541 | F10: =COUNTIFS(Achados!$B$2:$B$5723,$A10,Achados!$M$2:$M$5723,"sim") -> 232 | G10: =COUNTIFS(Achados!$B$2:$B$5723,$A10,Achados!$S$2:$S$5723,"Corrigido") -> 541 | H10: =IF(E10=0,0,G10/E10) -> 1
A11: 6 | B11: =COUNTIFS(Achados!$B$2:$B$5723,$A11,Achados!$G$2:$G$5723,"alta") -> 174 | C11: =COUNTIFS(Achados!$B$2:$B$5723,$A11,Achados!$G$2:$G$5723,"média") -> 361 | D11: =COUNTIFS(Achados!$B$2:$B$5723,$A11,Achados!$G$2:$G$5723,"baixa") -> 78 | E11: =SUM(B11:D11) -> 613 | F11: =COUNTIFS(Achados!$B$2:$B$5723,$A11,Achados!$M$2:$M$5723,"sim") -> 251 | G11: =COUNTIFS(Achados!$B$2:$B$5723,$A11,Achados!$S$2:$S$5723,"Corrigido") -> 613 | H11: =IF(E11=0,0,G11/E11) -> 1
A12: 7 | B12: =COUNTIFS(Achados!$B$2:$B$5723,$A12,Achados!$G$2:$G$5723,"alta") -> 115 | C12: =COUNTIFS(Achados!$B$2:$B$5723,$A12,Achados!$G$2:$G$5723,"média") -> 179 | D12: =COUNTIFS(Achados!$B$2:$B$5723,$A12,Achados!$G$2:$G$5723,"baixa") -> 65 | E12: =SUM(B12:D12) -> 359 | F12: =COUNTIFS(Achados!$B$2:$B$5723,$A12,Achados!$M$2:$M$5723,"sim") -> 156 | G12: =COUNTIFS(Achados!$B$2:$B$5723,$A12,Achados!$S$2:$S$5723,"Corrigido") -> 359 | H12: =IF(E12=0,0,G12/E12) -> 1
A13: 8 | B13: =COUNTIFS(Achados!$B$2:$B$5723,$A13,Achados!$G$2:$G$5723,"alta") -> 110 | C13: =COUNTIFS(Achados!$B$2:$B$5723,$A13,Achados!$G$2:$G$5723,"média") -> 245 | D13: =COUNTIFS(Achados!$B$2:$B$5723,$A13,Achados!$G$2:$G$5723,"baixa") -> 96 | E13: =SUM(B13:D13) -> 451 | F13: =COUNTIFS(Achados!$B$2:$B$5723,$A13,Achados!$M$2:$M$5723,"sim") -> 169 | G13: =COUNTIFS(Achados!$B$2:$B$5723,$A13,Achados!$S$2:$S$5723,"Corrigido") -> 451 | H13: =IF(E13=0,0,G13/E13) -> 1
A14: 9 | B14: =COUNTIFS(Achados!$B$2:$B$5723,$A14,Achados!$G$2:$G$5723,"alta") -> 178 | C14: =COUNTIFS(Achados!$B$2:$B$5723,$A14,Achados!$G$2:$G$5723,"média") -> 380 | D14: =COUNTIFS(Achados!$B$2:$B$5723,$A14,Achados!$G$2:$G$5723,"baixa") -> 92 | E14: =SUM(B14:D14) -> 650 | F14: =COUNTIFS(Achados!$B$2:$B$5723,$A14,Achados!$M$2:$M$5723,"sim") -> 204 | G14: =COUNTIFS(Achados!$B$2:$B$5723,$A14,Achados!$S$2:$S$5723,"Corrigido") -> 650 | H14: =IF(E14=0,0,G14/E14) -> 1
A15: 10 | B15: =COUNTIFS(Achados!$B$2:$B$5723,$A15,Achados!$G$2:$G$5723,"alta") -> 243 | C15: =COUNTIFS(Achados!$B$2:$B$5723,$A15,Achados!$G$2:$G$5723,"média") -> 744 | D15: =COUNTIFS(Achados!$B$2:$B$5723,$A15,Achados!$G$2:$G$5723,"baixa") -> 382 | E15: =SUM(B15:D15) -> 1369 | F15: =COUNTIFS(Achados!$B$2:$B$5723,$A15,Achados!$M$2:$M$5723,"sim") -> 354 | G15: =COUNTIFS(Achados!$B$2:$B$5723,$A15,Achados!$S$2:$S$5723,"Corrigido") -> 1369 | H15: =IF(E15=0,0,G15/E15) -> 1
A16: Total | B16: =SUM(B6:B15) -> 1530 | C16: =SUM(C6:C15) -> 3156 | D16: =SUM(D6:D15) -> 1036 | E16: =SUM(E6:E15) -> 5722 | F16: =SUM(F6:F15) -> 2053 | G16: =SUM(G6:G15) -> 5722 | H16: =IF(E16=0,0,G16/E16) -> 1
A19: Pendências da v5.0 por status na v5.2
A20: Status | B20: Checagem reprovada | C20: Conselho arriscado grave | D20: Amostra de achados graves | E20: Exemplo do mapa da v5.0 | F20: Total | G20: % do total
A21: corrigido | B21: =COUNTIFS('Pendências v5.0'!$I$2:$I$1079,$A21,'Pendências v5.0'!$B$2:$B$1079,"Checagem reprovada") -> 248 | C21: =COUNTIFS('Pendências v5.0'!$I$2:$I$1079,$A21,'Pendências v5.0'!$B$2:$B$1079,"Conselho arriscado grave") -> 21 | D21: =COUNTIFS('Pendências v5.0'!$I$2:$I$1079,$A21,'Pendências v5.0'!$B$2:$B$1079,"Amostra de achados graves") -> 104 | E21: =COUNTIFS('Pendências v5.0'!$I$2:$I$1079,$A21,'Pendências v5.0'!$B$2:$B$1079,"Exemplo do mapa da v5.0") -> 152 | F21: =SUM(B21:E21) -> 525 | G21: =IF($F$27=0,0,F21/$F$27) -> 0.49952426
A22: corrigido em parte | B22: =COUNTIFS('Pendências v5.0'!$I$2:$I$1079,$A22,'Pendências v5.0'!$B$2:$B$1079,"Checagem reprovada") -> 157 | C22: =COUNTIFS('Pendências v5.0'!$I$2:$I$1079,$A22,'Pendências v5.0'!$B$2:$B$1079,"Conselho arriscado grave") -> 7 | D22: =COUNTIFS('Pendências v5.0'!$I$2:$I$1079,$A22,'Pendências v5.0'!$B$2:$B$1079,"Amostra de achados graves") -> 132 | E22: =COUNTIFS('Pendências v5.0'!$I$2:$I$1079,$A22,'Pendências v5.0'!$B$2:$B$1079,"Exemplo do mapa da v5.0") -> 43 | F22: =SUM(B22:E22) -> 339 | G22: =IF($F$27=0,0,F22/$F$27) -> 0.32254995
A23: persiste | B23: =COUNTIFS('Pendências v5.0'!$I$2:$I$1079,$A23,'Pendências v5.0'!$B$2:$B$1079,"Checagem reprovada") -> 9 | C23: =COUNTIFS('Pendências v5.0'!$I$2:$I$1079,$A23,'Pendências v5.0'!$B$2:$B$1079,"Conselho arriscado grave") -> 2 | D23: =COUNTIFS('Pendências v5.0'!$I$2:$I$1079,$A23,'Pendências v5.0'!$B$2:$B$1079,"Amostra de achados graves") -> 16 | E23: =COUNTIFS('Pendências v5.0'!$I$2:$I$1079,$A23,'Pendências v5.0'!$B$2:$B$1079,"Exemplo do mapa da v5.0") -> 28 | F23: =SUM(B23:E23) -> 55 | G23: =IF($F$27=0,0,F23/$F$27) -> 0.052331113
A24: corrigido com erro novo | B24: =COUNTIFS('Pendências v5.0'!$I$2:$I$1079,$A24,'Pendências v5.0'!$B$2:$B$1079,"Checagem reprovada") -> 31 | C24: =COUNTIFS('Pendências v5.0'!$I$2:$I$1079,$A24,'Pendências v5.0'!$B$2:$B$1079,"Conselho arriscado grave") -> 8 | D24: =COUNTIFS('Pendências v5.0'!$I$2:$I$1079,$A24,'Pendências v5.0'!$B$2:$B$1079,"Amostra de achados graves") -> 25 | E24: =COUNTIFS('Pendências v5.0'!$I$2:$I$1079,$A24,'Pendências v5.0'!$B$2:$B$1079,"Exemplo do mapa da v5.0") -> 25 | F24: =SUM(B24:E24) -> 89 | G24: =IF($F$27=0,0,F24/$F$27) -> 0.084681256
A25: trecho removido | B25: =COUNTIFS('Pendências v5.0'!$I$2:$I$1079,$A25,'Pendências v5.0'!$B$2:$B$1079,"Checagem reprovada") -> 13 | C25: =COUNTIFS('Pendências v5.0'!$I$2:$I$1079,$A25,'Pendências v5.0'!$B$2:$B$1079,"Conselho arriscado grave") -> 3 | D25: =COUNTIFS('Pendências v5.0'!$I$2:$I$1079,$A25,'Pendências v5.0'!$B$2:$B$1079,"Amostra de achados graves") -> 23 | E25: =COUNTIFS('Pendências v5.0'!$I$2:$I$1079,$A25,'Pendências v5.0'!$B$2:$B$1079,"Exemplo do mapa da v5.0") -> 4 | F25: =SUM(B25:E25) -> 43 | G25: =IF($F$27=0,0,F25/$F$27) -> 0.040913416
A26: não localizado | B26: =COUNTIFS('Pendências v5.0'!$I$2:$I$1079,$A26,'Pendências v5.0'!$B$2:$B$1079,"Checagem reprovada") -> 0 | C26: =COUNTIFS('Pendências v5.0'!$I$2:$I$1079,$A26,'Pendências v5.0'!$B$2:$B$1079,"Conselho arriscado grave") -> 0 | D26: =COUNTIFS('Pendências v5.0'!$I$2:$I$1079,$A26,'Pendências v5.0'!$B$2:$B$1079,"Amostra de achados graves") -> 0 | E26: =COUNTIFS('Pendências v5.0'!$I$2:$I$1079,$A26,'Pendências v5.0'!$B$2:$B$1079,"Exemplo do mapa da v5.0") -> 0 | F26: =SUM(B26:E26) -> 0 | G26: =IF($F$27=0,0,F26/$F$27) -> 0
A27: Total | B27: =SUM(B21:B26) -> 458 | C27: =SUM(C21:C26) -> 41 | D27: =SUM(D21:D26) -> 300 | E27: =SUM(E21:E26) -> 252 | F27: =SUM(F21:F26) -> 1051 | G27: =IF($F$27=0,0,F27/$F$27) -> 1
A30: Checagem na web por veredito
A31: Veredito | B31: Esta conversa em casa serve para ouvir e alinhar limites reais, não para persuadir a família; o Capítulo 7 ajuda a apresentar seu plano com clareza | C31: % do checado
A32: erro confirmado | B32: =COUNTIF(Checagem!$G$2:$G$784,$A32) -> 275 | C32: =IF($B$37=0,0,B32/$B$37) -> 0.3525641
A33: desatualizado | B33: =COUNTIF(Checagem!$G$2:$G$784,$A33) -> 87 | C33: =IF($B$37=0,0,B33/$B$37) -> 0.11153846
A34: parcialmente certo | B34: =COUNTIF(Checagem!$G$2:$G$784,$A34) -> 783 | C34: =IF($B$37=0,0,B34/$B$37) -> 0.37051282
A35: correto no livro | B35: =COUNTIF(Checagem!$G$2:$G$784,$A35) -> 0 | C35: =IF($B$37=0,0,B35/$B$37) -> 0.11282051
A36: não verificável | B36: =COUNTIF(Checagem!$G$2:$G$784,$A36) -> 41 | C36: =IF($B$37=0,0,B36/$B$37) -> 0.052564103
A37: Total checado | B37: =SUM(B32:B36) -> 780 | C37: =IF($B$37=0,0,B37/$B$37) -> 1
A38: não checada | B38: =COUNTIF(Checagem!$G$2:$G$784,$A38) -> 3
A39: Total da aba | B39: =B37+B38 -> 783
A42: Checagem na web por tema (errado ou vencido = erro confirmado + desatualizado)
A43: Tema | B43: Checadas | C43: Errado ou vencido | D43: Parcialmente certo | E43: Correto no livro | F43: Não verificável | G43: % errado ou vencido
A44: Casos, pessoas e números | B44: =COUNTIFS(Checagem!$B$2:$B$784,$A44,Checagem!$G$2:$G$784,"<>não checada") -> 215 | C44: =COUNTIFS(Checagem!$B$2:$B$784,$A44,Checagem!$G$2:$G$784,"erro confirmado")+COUNTIFS(Checagem!$B$2:$B$784,$A44,Checagem!$G$2:$G$784,"desatualizado") -> 130 | D44: =COUNTIFS(Checagem!$B$2:$B$784,$A44,Checagem!$G$2:$G$784,"parcialmente certo") -> 59 | E44: =COUNTIFS(Checagem!$B$2:$B$784,$A44,Checagem!$G$2:$G$784,"correto no livro") -> 12 | F44: =COUNTIFS(Checagem!$B$2:$B$784,$A44,Checagem!$G$2:$G$784,"não verificável") -> 14 | G44: =IF(B44=0,0,C44/B44) -> 0.60465116
A45: Finanças e regulação | B45: =COUNTIFS(Checagem!$B$2:$B$784,$A45,Checagem!$G$2:$G$784,"<>não checada") -> 783 | C45: =COUNTIFS(Checagem!$B$2:$B$784,$A45,Checagem!$G$2:$G$784,"erro confirmado")+COUNTIFS(Checagem!$B$2:$B$784,$A45,Checagem!$G$2:$G$784,"desatualizado") -> 98 | D45: =COUNTIFS(Checagem!$B$2:$B$784,$A45,Checagem!$G$2:$G$784,"parcialmente certo") -> 292 | E45: =COUNTIFS(Checagem!$B$2:$B$784,$A45,Checagem!$G$2:$G$784,"correto no livro") -> 23 | F45: =COUNTIFS(Checagem!$B$2:$B$784,$A45,Checagem!$G$2:$G$784,"não verificável") -> 11 | G45: =IF(B45=0,0,C45/B45) -> 0.48514851
A46: Jurídico | B46: =COUNTIFS(Checagem!$B$2:$B$784,$A46,Checagem!$G$2:$G$784,"<>não checada") -> 123 | C46: =COUNTIFS(Checagem!$B$2:$B$784,$A46,Checagem!$G$2:$G$784,"erro confirmado")+COUNTIFS(Checagem!$B$2:$B$784,$A46,Checagem!$G$2:$G$784,"desatualizado") -> 49 | D46: =COUNTIFS(Checagem!$B$2:$B$784,$A46,Checagem!$G$2:$G$784,"parcialmente certo") -> 54 | E46: =COUNTIFS(Checagem!$B$2:$B$784,$A46,Checagem!$G$2:$G$784,"correto no livro") -> 15 | F46: =COUNTIFS(Checagem!$B$2:$B$784,$A46,Checagem!$G$2:$G$784,"não verificável") -> 5 | G46: =IF(B46=0,0,C46/B46) -> 0.39837398
A47: Tributário e trabalhista | B47: =COUNTIFS(Checagem!$B$2:$B$784,$A47,Checagem!$G$2:$G$784,"<>não checada") -> 200 | C47: =COUNTIFS(Checagem!$B$2:$B$784,$A47,Checagem!$G$2:$G$784,"erro confirmado")+COUNTIFS(Checagem!$B$2:$B$784,$A47,Checagem!$G$2:$G$784,"desatualizado") -> 78 | D47: =COUNTIFS(Checagem!$B$2:$B$784,$A47,Checagem!$G$2:$G$784,"parcialmente certo") -> 94 | E47: =COUNTIFS(Checagem!$B$2:$B$784,$A47,Checagem!$G$2:$G$784,"correto no livro") -> 23 | F47: =COUNTIFS(Checagem!$B$2:$B$784,$A47,Checagem!$G$2:$G$784,"não verificável") -> 5 | G47: =IF(B47=0,0,C47/B47) -> 0.39
...

Sheet Achados
A1: Nº | B1: Volume | C1: Linha | D1: Unidade | E1: Código | F1: Categoria | G1: Gravidade | H1: Trecho citado | I1: Problema | J1: Sugestão | K1: Recorrente | L1: Ocorrências estimadas | M1: Efeito da edição | N1: Pede checagem | O1: Checagem na web | P1: O que vale em out/2026 | Q1: Fonte da checagem | R1: Origem | S1: Status
A2: 1 | B2: 1 | C2: 24 | D2: NOTA DO AUTOR | E2: C2 | F2: Informação possivelmente desatualizada | G2: baixa | H2: muitos escritos no Vale do Silício por bilionários que operam com custo de capital próximo de zero | I2: Em 2026 o juro americano está longe de zero. O contraste com a Selic soa datado da era do juro zero, encerrada em 2022. | J2: Datar ou trocar: "escritos na década do dinheiro barato" ou "por bilionários com acesso a capital farto". | K2: não | L2: 1 | M2: não | N2: sim | R2: Revisor de trecho | S2: Corrigido
A3: 2 | B3: 1 | C3: 30 | D3: NOTA DO AUTOR | E3: N7 | F3: Autoridade forçada ou atribuição duvidosa | G3: média | H3: nos rituais práticos de segunda-feira às nove da manhã de **Gino Wickman** (*Traction*) | I3: Dez autores em dois parágrafos, com atribuições forçadas. O EOS de Wickman não fixa ritual na segunda às 9h, e Collins e Christensen não escrevem sobre medo, demissões e caixa. | J3: Ficar com quatro nomes e dizer o que cada um deu de concreto (Gerber: técnico não é empresário. Wickman: a reunião semanal de 90 minutos). Tirar Collins e Christensen da frase sobre medo e demissões. | K3: não | L3: 1 | M3: não | N3: não | R3: Revisor de trecho | S3: Corrigido
A4: 3 | B4: 1 | C4: 36 | D4: NOTA DO AUTOR | E4: C5 | F4: Contradição interna | G4: alta | H4: impressos uma única vez na coleção inteira, exatamente na etapa em que entram em ação. | I4: Desmentido na l. 50 ("presença local das ferramentas compartilhadas"), no callout "Uso autocontido" (l. 629) e no pre-mortem, impresso na Fase 0 e de novo no Cap. 6 (l. 4916). | J4: Escolher a regra e escrevê-la igual nos dois lugares. Se cada ferramenta sai uma vez, cortar a ressalva da l. 50 e o roteiro de pre-mortem do Cap. 6. A frase da l. 50 ainda termina solta em "e com o Dicionário Geral Unificado". | K4: não | L4: 1 | M4: sim | N4: não | R4: Revisor de trecho | S4: Corrigido
A5: 4 | B5: 1 | C5: 38 | D5: NOTA DO AUTOR | E5: N9 | F5: Título que promete o que o corpo não entrega | G5: média | H5: abra a Oficina de Trincheira quando precisar agir sob pressão. | I5: Nenhuma seção dos 10 volumes se chama Oficina de Trincheira ou Caderno de Campo. Na Fase 0 as ferramentas estão em MANUAL PASSO A PASSO, CANVASES VISUAIS e TEMPLATES OPERACIONAIS. | J5: Dar o nome ao bloco de ferramentas de cada fase ("Oficina de Trincheira: frameworks, canvas e templates") ou trocar o nome na Nota e na l. 157 pelo que o leitor vai achar no sumário. | K5: não | L5: 1 | M5: sim | N5: não | R5: Revisor de trecho | S5: Corrigido
A6: 5 | B6: 1 | C6: 38 | D6: NOTA DO AUTOR | E6: E9 | F6: Erro gramatical ou frase corrompida | G6: baixa | H6: Leia os capítulos corridos para mudar a sua forma de enxergar o jogo; abra a Oficina de Trincheira | I6: Ponto e vírgula unindo duas ordens que pedem ponto, contra a regra do autor. Há 3 no material de abertura. | J6: "Leia os capítulos corridos para mudar o jeito de enxergar o jogo. Abra as ferramentas quando precisar agir sob pressão." | K6: sim | L6: 3 | M6: não | N6: não | R6: Revisor de trecho | S6: Corrigido
A7: 6 | B7: 1 | C7: 50 | D7: SOBRE ESTE LIVRO | E7: C5 | F7: Contradição interna | G7: baixa | H7: **39 Templates operacionais prontos para uso** | I7: Há 43 cabeçalhos "#### Template" nos 10 volumes (frameworks 164 e canvases 20 batem). E "~915 mil palavras" (l. 85) não bate com as cerca de 960 mil da v5.2. | J7: Recontar depois da edição e atualizar os dois números, ou arredondar ("cerca de 40 templates", "quase um milhão de palavras"). | K7: não | L7: 1 | M7: sim | N7: sim | R7: Revisor de trecho | S7: Corrigido
A8: 7 | B8: 1 | C8: 62 | D8: SOBRE ESTE LIVRO | E8: E9 | F8: Erro gramatical ou frase corrompida | G8: média | H8: Fases 19 e 20 e 21 Capítulos de Conselho de Administração (Board) | I8: Lê-se como Fases 19, 20 e 21. O mesmo tropeço em "Fase 14 e 15 Capítulos" (l. 58), "Fases 15 e 16 e 15 Capítulos" (l. 59), "Fase 17 e 10" e "Fase 18 e 13". | J8: Separar fase de contagem: "Fases 19 e 20, mais 21 capítulos sobre conselho...". Aplicar do Vol. 5 ao 9. | K8: sim | L8: 5 | M8: não | N8: não | R8: Revisor de trecho | S8: Corrigido
A9: 8 | B9: 1 | C9: 72 | D9: ABERTURA DO VOL. 1 (ARQUÉTIPOS) | E9: N3 | F9: Arquétipo inconsistente, decorativo ou ausente | G9: média | H9: você acompanhará de forma equilibrada em cada fase a evolução | I9: Não há equilíbrio. Das 21 fases, Lucas e Marina abrem 10, Camila 4, Rafael e Bia 4 e Henrique 3. Henrique não abre fase nenhuma depois do Vol. 4, como na v5.0. | J9: Dar a Henrique uma fase dos Vols. 5 a 9 (a Fase 19, segunda curva, com o spin-off, é a candidata natural) ou trocar 'de forma equilibrada em cada fase' por 'ao longo da coleção'. | K9: não | L9: 1 | M9: sim | N9: não | R9: Leitura cruzada dos arquétipos | S9: Corrigido
A10: 9 | B10: 1 | C10: 72 | D10: ABERTURA DO VOLUME | E10: N3 | F10: Arquétipo inconsistente, decorativo ou ausente | G10: média | H10: você acompanhará de forma equilibrada em cada fase a evolução | I10: A dupla abre 51 das 128 unidades dos Vols. 1 a 9 (40%) e assina 68 dos 175 moldes. Camila abre cerca de 22 (17%). O equilíbrio prometido não existe. | J10: Passar aberturas da dupla nos Vols. 6 e 7 para Camila e para Rafael e Bia, ou trocar a promessa por "com o arquétipo que melhor ilustra cada tema". | K10: não | L10: 1 | M10: não | N10: não | R10: Leitura cruzada dos arquétipos | S10: Corrigido
A11: 10 | B11: 1 | C11: 72 | D11: OS 4 FUNDADORES (TABELA) | E11: N3 | F11: Arquétipo inconsistente, decorativo ou ausente | G11: média | H11: você acompanhará de forma equilibrada em cada fase a evolução, os tropeços financeiros, os impasses societários, os pivôs e as vitórias de **quatro arquétipos | I11: Na Fase 0 só Camila tem arco. Henrique é um nome na l. 169, Rafael e Bia aparecem num exemplo corrompido (l. 968), Lucas e Marina num desfecho de molde (l. 604). | J11: Atenuar ("os quatro ao longo do volume, um ou dois por fase") ou dar a cada um uma cena curta. Ex.: Henrique faz o Teste do Extrato com a renda irregular de quem vende para prefeituras. | K11: não | L11: 1 | M11: não | N11: não | R11: Revisor de trecho | S11: Corrigido
A12: 11 | B12: 1 | C12: 76 | D12: OS 4 FUNDADORES (TABELA) | E12: E7 | F12: Anglicismo ou mistura founder/fundador | G12: média | H12: negociam *Series A* em São Paulo | I12: Contra a regra do autor (Série A). A tabela também acumula glosas: churn (cancelamento de clientes), M&A (fusão e aquisição), Spin-off (cisão societária). | J12: "negociam a Série A em São Paulo". Deixar as glosas para o Dicionário do Vol. 10 ou para a primeira ocorrência no texto corrido. | K12: não | L12: 1 | M12: não | N12: não | R12: Revisor de trecho | S12: Corrigido
A13: 12 | B13: 1 | C13: 77 | D13: OS 4 FUNDADORES (TABELA) | E13: C3 | F13: Erro factual provável | G13: média | H13: Compra equipamento caro por impulso (*custo afundado*) | I13: Comprar por impulso não é custo afundado. A falácia é insistir num gasto ruim porque já se pagou por ele. O rótulo ensina o conceito errado. | J13: "Compra equipamento caro por impulso e depois insiste nele para não admitir a perda (falácia do custo afundado)". | K13: não | L13: 1 | M13: não | N13: não | R13: Revisor de trecho | S13: Corrigido
... A33: 32 | B33: 1 | C33: 165 | D33: FASE 0 | E33: N1 | F33: Abertura sem tensão ou em fórmula | G33: média | H33: Ao longo desta Fase 0, Camila refaz essa conta pelo método do Passo 1 (separando o piso de sobrevivência doméstica do capital da clínica), senta com o marido no Passo 4 | I33: A cena entrega o arco inteiro no primeiro parágrafo, em forma de índice de passos. A tensão do cheque especial morre antes de o corpo começar. | J33: Parar a cena no risco: "se levasse mais de quatro meses para empatar, a família entraria no cheque especial". Mostrar Camila de novo no Passo 1, no Passo 4 e no Espelho. | K33: não | L33: 1 | M33: não | N33: não | R33: Revisor de trecho | S33: Corrigido
A34: 33 | B34: 1 | C34: 167 | D34: FASE 0 | E34: E9 | F34: Erro gramatical ou frase corrompida | G34: alta | H34: encerra muito mais negócios na largada do que a escassez de boas ideias, quando na vida real a maioria morre porque o fundador quebrou emocional ou financeiramente seis meses antes | I34: O "quando" cola duas teses e desmente a primeira. A segunda ("a maioria morre porque o fundador quebrou") fica atribuída ao Sebrae, que não mede isso. | J34: Partir: "Os estudos de sobrevivência do Sebrae apontam falta de planejamento e de capital de giro. Na prática, o fundador costuma quebrar antes do negócio." Tirar o negrito da frase inteira. | K34: não | L34: 1 | M34: sim | N34: sim | O34: parcialmente certo | P34: Os estudos do Sebrae-SP atribuem o fechamento a uma soma de fatores: falta de planejamento prévio, gestão fraca, comportamento empreendedor, economia, políticas públicas e problemas pessoais. Falta de capital aparece como dificuldade. Nenhum mede que a maioria morre porque o fundador quebrou. | Q34: https://www.legisweb.com.br/noticia/?id=895 | R34: Revisor de trecho | S34: Corrigido
A35: 34 | B35: 1 | C35: 174 | D35: FASE 0 | E35: S4 | F35: Remissão quebrada ou em excesso | G35: alta | H35: leia da abertura até o fim de "Permissão para dizer 'ainda não'" e pare. | I35: Não existe seção com esse título. Virou "Quando não empreender agora" (l. 180). A l. 564 repete a remissão para o título antigo. | J35: "leia até o fim de 'Quando não empreender agora: os 10 sinais' e pare". Corrigir também a l. 564. | K35: não | L35: 1 | M35: sim | N35: não | R35: Revisor de trecho | S35: Corrigido
A36: 35 | B36: 1 | C36: 178 | D36: FASE 0 | E36: E1 | F36: Antítese "não é X, é Y" | G36: média | H36: A maioria das desistências não acontece porque a ideia era ruim. Acontece porque o empreendedor não aguentou a pressão. | I36: Antítese "não é X, é Y" em série na fase: l. 182, 272, 370, 386, 612, 694, 949, 1318 e outras. Vira cadência de molde. | J36: Manter duas que carregam tese (a permissão da l. 612, a de Ivanov na l. 949). Nas outras, afirmar direto: "A maioria desiste porque não aguenta a pressão." | K36: sim | L36: 16 | M36: não | N36: não | R36: Revisor de trecho | S36: Corrigido
A37: 36 | B37: 1 | C37: 214 | D37: FASE 0 | E37: E9 | F37: Erro gramatical ou frase corrompida | G37: alta | H37: Retorno financeiro real, quando vem, vem em sete a doze. | I37: Frase truncada, sem a unidade. O prazo também não sai de Hamilton (2000), que achou renda menor mesmo depois de dez anos. | J37: "Quando vem, o retorno financeiro real costuma chegar entre o sétimo e o décimo segundo ano." Deixar claro o que é dado de Hamilton e o que é estimativa do autor. | K37: não | L37: 1 | M37: sim | N37: sim | O37: erro confirmado | P37: Hamilton (2000) achou renda inicial menor e crescimento de renda menor que no emprego, com diferença mediana de 35% para quem está no negócio há 10 anos. O prazo de sete a doze anos não vem dele, e a frase do livro está truncada, sem 'anos'. | Q37: https://profiles.wustl.edu/en/publications/does-entrepreneurship-pay-an-empirical-analysis-of-the-returns-to/ | R37: Revisor de trecho | S37: Corrigido
A38: 37 | B38: 1 | C38: 220 | D38: FASE 0 | E38: E9 | F38: Erro gramatical ou frase corrompida | G38: alta | H38: Aos país que dizem "estabilize". | I38: "país" (nação) no lugar de "pais". Repete na l. 254: "sobre cônjuge, país ou amigos próximos". Provável correção automática de acento. | J38: "Aos pais que dizem 'estabilize'." e "sobre cônjuge, pais ou amigos próximos". | K38: sim | L38: 2 | M38: sim | N38: não | R38: Revisor de trecho | S38: Corrigido
A39: 38 | B39: 1 | C39: 231 | D39: FASE 0 | E39: C5 | F39: Contradição interna | G39: alta | H39: Os sinais 1 e 2 (reserva financeira inexistente e quadro agudo de saúde mental sem tratamento) são eliminatórios por si sós | I39: O sinal 2 é período emocionalmente turbulento. Saúde mental sem tratamento é o sinal 9. O leitor que se avalia aplica a regra eliminatória ao sinal errado. | J39: "Os sinais 1 e 9 (reserva inexistente e saúde mental sem tratamento)". Conferir se a ordem da lista mudou nesta edição. | K39: não | L39: 1 | M39: sim | N39: não | R39: Revisor de trecho | S39: Corrigido
A40: 39 | B40: 1 | C40: 242 | D40: FASE 0 | E40: C5 | F40: Contradição interna | G40: alta | H40: Se for menor que seis meses, não peça demissão agora: valide em paralelo ao emprego. | I40: Dá a entender que 6 meses bastam para sair. Fluxograma (l. 186), Passo 7, números (l. 334) e alerta (l. 623) pedem 12 para dedicação integral. Conselho financeiro arriscado. | J40: "Abaixo de 12 meses, não peça demissão. Entre 6 e 12, valide em paralelo ao emprego. Abaixo de 6, monte reserva antes de começar." | K40: não | L40: 1 | M40: não | N40: não | R40: Revisor de trecho | S40: Corrigido
A41: 40 | B41: 1 | C41: 242 | D41: FASE 0 | E41: S4 | F41: Remissão quebrada ou em excesso | G41: alta | H41: consulte um advogado trabalhista e veja os Capítulos 4 e 7 do Vol. 8) | I41: O Cap. 7 do Vol. 8 é Direito do Consumidor. Justa causa está no Cap. 6 (Trabalho) e titularidade de software no Cap. 3 (Propriedade Intelectual). | J41: "veja os Capítulos 3, 4 e 6 do Vol. 8". | K41: não | L41: 1 | M41: sim | N41: não | R41: Revisor de trecho | S41: Corrigido
A42: 41 | B42: 1 | C42: 253 | D42: FASE 0 | E42: E11 | F42: Registro inconsistente ou tom de coach | G42: média | H42: Esta conversa em casa serve para ouvir e alinhar limites reais, não para persuadir a família; o Capítulo 7 ajuda a apresentar seu plano com clareza | I42: Título de callout virou parágrafo com ponto e vírgula. E o corpo contradiz o título: chama o capítulo de persuasão de "ferramenta direta para a conversa desta etapa". | J42: Título curto: "Ouvir antes de convencer". Corpo: "O Capítulo 7 ajuda a expor o plano com clareza. Se o cônjuge recusar com bons motivos, isso entra na decisão como dado." | K42: não | L42: 1 | M42: sim | N42: não | R42: Revisor de trecho | S42: Corrigido
A43: 42 | B43: 1 | C43: 263 | D43: FASE 0 | E43: C5 | F43: Contradição interna | G43: média | H43: parcial em paralelo ao emprego (*part-time*, de 10 a 20 horas semanais, com reserva mínima de 6 meses) | I43: A l. 335 dá 15 a 25 horas para o meio período. A trava (l. 538) exige 10 horas protegidas, o teto do projeto lateral (5 a 10). | J43: Uma tabela única e repetida igual: lateral 5 a 10 h, parcial 15 a 20 h, integral 40 h ou mais. Usar no Passo 7, nos números da l. 335 e na trava. | K43: não | L43: 1 | M43: não | N43: não | R43: Revisor de trecho | S43: Corrigido
A44: 43 | B44: 1 | C44: 272 | D44: FASE 0 | E44: C1 | F44: Dado sem fonte ou precisão inventada | G44: média | H44: São observações baseadas na experiência de ter acompanhado mais de três mil fundadores no Y Combinator | I44: Os ensaios citados são de 2008 a 2010, quando a YC tinha financiado poucas centenas de empresas. Mesmo até 2014 o número parece inflado. | J44: "baseadas nas centenas de fundadores que Graham acompanhou na YC", ou tirar o número. | K44: não | L44: 1 | M44: não | N44: sim | R44: Revisor de trecho | S44: Corrigido
A45: 44 | B45: 1 | C45: 277 | D45: FASE 0 | E45: S5 | F45: Duplicação com outro capítulo ou volume | G45: média | H45: Outros três do mesmo autor (*What We Look for in Founders*, *Before the Startup* e *You Weren't Meant to Have a Boss*) entram resumidos | I45: What We Look for in Founders já está no título do terceiro ensaio (l. 310) e volta resumido na l. 326. Os "três mais três" são cinco. | J45: Tirar o ensaio do título da l. 310 (a imagem do running back pode ser citada sem virar seção) ou do resumo da l. 326. Ajustar a contagem. | K45: não | L45: 1 | M45: não | N45: não | R45: Revisor de trecho | S45: Corrigido
A46: 45 | B46: 1 | C46: 285 | D46: FASE 0 | E46: E9 | F46: Erro gramatical ou frase corrompida | G46: baixa | H46: Loops abertos são imãs mentais que roubam a sua capacidade de pensar em trabalho profundo. | I46: Grafias fora do padrão em série: imãs (ímãs), auto-exclusão, auto-crítica, subrepresentar, contra-medidas, "o por quê", "Por quê melhor?", "Independente do modelo". | J46: Corrigir: ímãs, autoexclusão, autocrítica, sub-representar, contramedidas, o porquê, "Por que melhor?", Independentemente. | K46: sim | L46: 9 | M46: não | N46: não | R46: Revisor de trecho | S46: Corrigido
A47: 46 | B47: 1 | C47: 308 | D47: FASE 0 | E47: N7 | F47: Autoridade forçada ou atribuição duvidosa | G47: baixa | H47: A formulação é uma síntese das duas teses centrais que Graham repete em ensaios e palestras, não citação literal de uma única frase. | I47: O ensaio Be Relentlessly Resourceful parece trazer a frase quase literal (destino e caminho). Se trouxer, a ressalva está errada. | J47: Conferir no ensaio. Se a frase estiver lá, citar a fonte e cortar a ressalva. | K47: não | L47: 1 | M47: não | N47: sim | R47: Revisor de trecho | S47: Corrigido
A48: 47 | B48: 1 | C48: 341 | D48: FASE 0 | E48: E3 | F48: Adjetivo inflado ou intensificador | G48: média | H48: Reconhecer os sinais cedo é crítico. | I48: Intensificador vazio em série: crítico (l. 249, 251, 341, 411, 477, 818), essencial (388, 772, 1248), profundo (411, 578, 580). Cerca de 25 na fase. | J48: Cortar o adjetivo ou dizer o porquê: "Reconheça os sinais cedo. Nesta fase o burnout se disfarça de procrastinação." | K48: sim | L48: 25 | M48: não | N48: não | R48: Revisor de trecho | S48: Corrigido
A49: 48 | B49: 1 | C49: 353 | D49: FASE 0 | E49: E9 | F49: Erro gramatical ou frase corrompida | G49: média | H49: Founder em Fase 0 vê anúncio de rodada de seed (primeira rodada de investimento externo) de par: e não vê os 18 meses de rejeição que antecederam. | I49: Dois-pontos antes de "e" quebra a frase, provável troca mecânica de travessão. "Founder" e "Social media" no mesmo trecho. | J49: "O fundador em Fase 0 vê o anúncio da rodada seed de um colega e não vê os 18 meses de recusa que vieram antes. Rede social como régua emocional nesta fase envenena devagar." | K49: não | L49: 1 | M49: sim | N49: não | R49: Revisor de trecho | S49: Corrigido
... A68: 67 | B68: 1 | C68: 566 | D68: FASE 0 | E68: C5 | F68: Contradição interna | G68: média | H68: Aplique a regra da **reserva ÷ (custo mínimo mensal × 1,5)**: o fator de 1,5 cobre o custo imprevisto que você esqueceu de listar, enquanto dividir a receita projetada por dois | I68: Segunda fórmula de runway, sem dizer a qual delas valem os limites de 6 e 12 meses. "Dividir a receita projetada por dois" não está na fórmula. | J68: Uma fórmula só (a conservadora, que o Ritual usa) e os limites calculados sobre ela. Se a receita entra, escrever: reserva ÷ (custo mínimo × 1,5 menos metade da receita mensal esperada). | K68: não | L68: 1 | M68: não | N68: não | R68: Revisor de trecho | S68: Corrigido
A69: 68 | B69: 1 | C69: 578 | D69: FASE 0 | E69: C3 | F69: Erro factual provável | G69: média | H69: Em 2013, David Vélez era sócio da Sequoia Capital. | I69: Em 2013 Vélez já fundava o Nubank, e a l. 702 o chama de ex-Sequoia no mesmo ano. O cargo de sócio também é duvidoso. | J69: "Vélez tinha passado por Morgan Stanley, General Atlantic e Sequoia, onde estudava a América Latina." Alinhar com a l. 702. | K69: não | L69: 1 | M69: não | N69: sim | O69: parcialmente certo | P69: Vélez passou por Morgan Stanley, Goldman Sachs e General Atlantic e chegou a sócio da Sequoia, que em 2011 o encarregou de abrir frente no Brasil, plano depois engavetado. Em 2013, aos 31 anos, ele cofundou o Nubank, e por isso não era mais da Sequoia naquele ano. | Q69: https://en.wikipedia.org/wiki/David_V%C3%A9lez | R69: Revisor de trecho | S69: Corrigido
A70: 69 | B70: 1 | C70: 592 | D70: FASE 0 | E70: S6 | F70: Seção desproporcional ou fora de lugar | G70: média | H70: você precisa responder por que a sua trajetória específica conversa com a dor escolhida e quanto tempo o seu caixa pessoal sustenta a travessia | I70: O caso não diz nada sobre caixa pessoal. Metade dele é PMF, rodadas e IPO, e três das quatro lições (crédito, NPS, captação) são das Fases 11 a 14. | J70: Cortar "Travessia ao PMF" e "Do PMF à escala" (ou levar à Fase 13). Na Fase 0, ficar com a complementaridade dos três e com o que cada um arriscou ao largar o emprego. | K70: não | L70: 1 | M70: não | N70: não | R70: Revisor de trecho | S70: Corrigido
A71: 70 | B71: 1 | C71: 596 | D71: FASE 0 | E71: C5 | F71: Contradição interna | G71: média | H71: 3. **NPS sustentado acima de 80** é raro e gera efeito composto | I71: A l. 586 trata o NPS de 80 como relato que varia. A lição vira fato. A lição 4 ("diluição abaixo da média") não tem fonte, e a seed de 2013 veio antes de qualquer marco. | J71: "NPS alto, perto de 80 em relatos da empresa, é raro em serviços financeiros e...". Na lição 4, cortar a diluição ou dar número com fonte. | K71: não | L71: 1 | M71: não | N71: não | R71: Revisor de trecho | S71: Corrigido
A72: 71 | B72: 1 | C72: 604 | D72: FASE 0 | E72: N3 | F72: Arquétipo inconsistente, decorativo ou ausente | G72: alta | H72: permitiu que **Lucas e Marina**, a partir de São Paulo e Florianópolis, blindassem a margem operacional e reduzissem o retrabalho da equipe. | I72: A Fase 0 é de Camila: abre com ela (1:165) e volta no Espelho (1:608) e no fechamento (1:1316). O molde dá o desfecho a Lucas e Marina, na primeira unidade do livro. | J72: Cortar o molde. O item 1 do Espelho (1:608) e o fechamento já retomam Camila. | K72: não | L72: 1 | M72: sim | N72: não | R72: Leitura cruzada dos arquétipos | S72: Corrigido
A73: 72 | B73: 1 | C73: 604 | D73: FASE 0 | E73: S7 | F73: Artefato de formatação ou texto de bastidor | G73: alta | H73: **Resultado na trincheira (PREPARAÇÃO DO EMPREENDEDOR):** A disciplina descrita em *O Espelho da Fase 0 e o Ritual de Segunda-Feira* permitiu que **Lucas e Marina** | I73: Desfecho de molde. A fase é de Camila, e Lucas e Marina não têm margem operacional nem equipe na Fase 0. Vem antes do Espelho que diz resumir. | J73: Cortar. Se quiser um resultado, usar Camila: "Com 14 meses de reserva, Camila assinou a locação sem entrar no cheque especial." | K73: não | L73: 1 | M73: sim | N73: não | R73: Revisor de trecho | S73: Corrigido
A74: 73 | B74: 1 | C74: 604 | D74: FASE 0 | E74: N3 | F74: Arquétipo inconsistente, decorativo ou ausente | G74: média | H74: permitiu que **Lucas e Marina**, a partir de São Paulo e Florianópolis, blindassem a margem operacional e reduzissem o retrabalho da equipe. | I74: Molde com a dupla numa fase aberta por Camila. Fala em margem e equipe quando a dupla nem tem empresa: a ideia nasce na Fase 1 e a folha é zero (1:6189). | J74: Cortar o molde ou fechar com Camila e a cena dela, o orçamento da casa separado do Pix da clínica. | K74: não | L74: 1 | M74: sim | N74: não | R74: Leitura cruzada dos arquétipos | S74: Corrigido
A75: 74 | B75: 1 | C75: 608 | D75: FASE 0 | E75: C5 | F75: Contradição interna | G75: alta | H75: (Quando a Dra. Camila fez essa conta em Belo Horizonte antes de ampliar a clínica, somou 9 pontos nas três perguntas e adiou a reforma em três meses até recompor a reserva.), sua família dorme em paz | I75: Na Fase 0 Camila ainda vai abrir a clínica e só assina o ponto com 14 meses de reserva (1:165, 1:1320). 'Ampliar' e 'reforma' contradizem isso. O parêntese ainda parte a pergunta ao meio. | J75: Tirar o parêntese da pergunta e pôr no fim do item: 'Quando Camila fez essa conta, somou 9 pontos e adiou a assinatura do ponto comercial até juntar 14 meses de reserva.' | K75: não | L75: 1 | M75: sim | N75: não | R75: Leitura cruzada dos arquétipos | S75: Corrigido
A76: 75 | B76: 1 | C76: 608 | D76: FASE 0 | E76: E9 | F76: Erro gramatical ou frase corrompida | G76: alta | H76: somou 9 pontos nas três perguntas e adiou a reforma em três meses até recompor a reserva.), sua família dorme em paz ou você precisará tomar decisões desesperadas no mês 5? | I76: Parêntese enxertado no meio da pergunta. Depois de ".)" a frase segue com vírgula e perde o sujeito. | J76: "...sem vender patrimônio essencial? Sua família dorme em paz ou você vai decidir no desespero no mês 5?" O exemplo de Camila vai para uma frase própria depois da pergunta. | K76: não | L76: 1 | M76: sim | N76: não | R76: Revisor de trecho | S76: Corrigido
A77: 76 | B77: 1 | C77: 608 | D77: FASE 0 | E77: C5 | F77: Contradição interna | G77: alta | H77: Quando a Dra. Camila fez essa conta em Belo Horizonte antes de ampliar a clínica | I77: Na abertura Camila acabou de sair do emprego e nem assinou o ponto. Aqui amplia clínica e adia reforma. E "9 pontos nas três perguntas" não tem escala: só a 1ª é pontuada. | J77: Retomar a abertura: "No domingo da cena, Camila tirou 2 no Teste do Extrato. Só assinou a locação quando a nota chegou a 5, com 14 meses de reserva." Dar nota de 1 a 5 às três perguntas. | K77: não | L77: 1 | M77: não | N77: não | R77: Revisor de trecho | S77: Corrigido
...

Sheet Pendências v5.0
A1: ID | B1: Conjunto | C1: Vol. (v5.0) | D1: Linha (v5.0) | E1: Categoria | F1: Trecho na v5.0 | G1: Problema apontado | H1: O que vale (checagem de out/2026) | I1: Status na v5.2 | J1: Vol. (v5.2) | K1: Linha (v5.2) | L1: Trecho na v5.2 | M1: Também aparece em | N1: Nota | O1: Status
A2: DA-073 | B2: Exemplo do mapa da v5.0 | C2: 1 | D2: 38 | E2: Estrutura e navegação > Promessas da Nota do autor | F2: O rótulo Atos 1 a 4 não aparece em nenhum capítulo | G2: O rótulo Atos 1 a 4 não aparece em nenhum capítulo | I2: corrigido | J2: 1 | K2: 35 | L2: 1. **A Narrativa Viva:** abro sempre no meio da tensão real | N2: A Nota trocou Atos 1 a 4 por A Narrativa Viva. O rótulo não aparece mais. | O2: Corrigido
A3: DA-075 | B3: Exemplo do mapa da v5.0 | C3: 1 | D3: 39 | E3: Estrutura e navegação > Promessas da Nota do autor | F3: Caderno de Campo só aparece na própria Nota do autor | G3: Caderno de Campo só aparece na própria Nota do autor | I3: persiste | J3: 1 | K3: 36 | L3: 2. **A Oficina de Trincheira (Caderno de Campo):** | N3: Continua sendo a única menção na coleção. A mesma frase agora promete ferramentas impressas uma única vez, enquanto Sobre este livro (l. 50) fala em presença local das ferramentas compartilhadas. | O3: Corrigido
A4: DA-028 | B4: Exemplo do mapa da v5.0 | C4: 1 | D4: 629 | E4: Vícios de escrita | F4: Rótulo didático: Lições transferíveis. no caso Nubank da Fase 0 | G4: Rótulo didático: Lições transferíveis. no caso Nubank da Fase 0 | I4: corrigido | J4: 1 | K4: 592 | L4: **O que esse início ensina a quem ainda está na Fase 0:** antes de discutir produto ou rodada de investimento | N4: No Vol. 1 o rótulo virou frase. O mesmo rótulo segue no Vol. 9 (l. 5533, 5614 e 5702), fora do exemplo do mapa. | O4: Corrigido
A5: DA-257 | B5: Exemplo do mapa da v5.0 | C5: 1 | D5: 649 | E5: Mapa por volume | F5: Vol. 1: fórmula de runway corrompida no Ritual da Fase 0 | G5: Vol. 1: fórmula de runway corrompida no Ritual da Fase 0 | I5: corrigido | J5: 1 | K5: 614 | L5: pela fórmula `reserva líquida ÷ (custo mensal mínimo × 1,5)` | N5: O LaTeX quebrado saiu e a margem de 50% agora reduz o runway, em vez de aumentá-lo. | O5: Corrigido
A6: DA-231 | B6: Exemplo do mapa da v5.0 | C6: 1 | D6: 736 | E6: Conteúdo e precisão > Capítulos que se dizem atuais | F6: Walgreens fechou capital (Vol. 1) | G6: Walgreens fechou capital (Vol. 1) | I6: corrigido | J6: 1 | K6: 667 | L6: Walgreens até seu fechamento de capital pela Sycamore Partners em agosto de 2025 | N6: O exemplo de Collins ganhou a ressalva. | O6: Corrigido
A7: DA-076 | B7: Exemplo do mapa da v5.0 | C7: 1 | D7: 1220 | E7: Estrutura e navegação > Remissões com numeração antiga | F7: Team Canvas na Fase 14 (escala e time), deveria ser Fases 15 e 16 | G7: Team Canvas na Fase 14 (escala e time), deveria ser Fases 15 e 16 | I7: corrigido | J7: 1 | K7: 945 | L7: Volte a ele na Fase 16, ao montar a liderança ou ao montar equipe de liderança expandida. | N7: Número certo. A frase nova repete ao montar duas vezes. | O7: Corrigido
A8: DA-061 | B8: Exemplo do mapa da v5.0 | C8: 1 | D8: 1622 | E8: Narrativa > O que funciona e deve ficar | F8: Batismo do conceito: Síndrome da Ideia de Vitrine | G8: Batismo do conceito: Síndrome da Ideia de Vitrine | I8: persiste | J8: 1 | K8: 1332 | L8: Da pergunta de Marina nasce o diagnóstico desta fase, a **Síndrome da Ideia de Vitrine** | N8: Qualidade preservada na abertura da Fase 1. | O8: Corrigido
A9: DA-077 | B9: Exemplo do mapa da v5.0 | C9: 1 | D9: 2451 | E9: Estrutura e navegação > Remissões com numeração antiga | F9: Lean Canvas até a Fase 12 (PMF), deveria ser Fase 13 | G9: Lean Canvas até a Fase 12 (PMF), deveria ser Fase 13 | I9: corrigido | J9: 1 | K9: 1992 | L9: Use o Lean Canvas a partir da Fase 1 (encontrar a ideia) até a Fase 13 (PMF). | N9: Corrigido na única cópia que restou do canvas. | O9: Corrigido
A10: DA-078 | B10: Exemplo do mapa da v5.0 | C10: 1 | D10: 2548 | E10: Estrutura e navegação > Remissões com numeração antiga | F10: Strategy Canvas na Fase 5 (mapeamento de mercado e concorrência), deveria ser Fase 6 | G10: Strategy Canvas na Fase 5 (mapeamento de mercado e concorrência), deveria ser Fase 6 | I10: corrigido | J10: 2 | K10: 4635 | L10: Use o Strategy Canvas na Fase 6 (mapeamento de mercado e concorrência) | N10: A cópia do Vol. 1 saiu. O canvas ficou só no Vol. 2, com o número certo. | O10: Corrigido
A11: DA-079 | B11: Exemplo do mapa da v5.0 | C11: 1 | D11: 2548 | E11: Estrutura e navegação > Remissões com numeração antiga | F11: Strategy Canvas na Fase 15 (reinvenção), deveria ser Fase 19 | G11: Strategy Canvas na Fase 15 (reinvenção), deveria ser Fase 19 | I11: corrigido | J11: 2 | K11: 4635 | L11: retome a ferramenta na Fase 19 (reinvenção e segunda curva, no Volume 9). | N11: Corrigido na única cópia do canvas. | O11: Corrigido
A12: DA-080 | B12: Exemplo do mapa da v5.0 | C12: 1 | D12: 4079 | E12: Estrutura e navegação > Remissões com numeração antiga | F12: Opportunity Canvas na Fase 8 (ideação), deveria ser Fase 9 | G12: Opportunity Canvas na Fase 8 (ideação), deveria ser Fase 9 | I12: corrigido | J12: 3 | K12: 2469 | L12: Use o Opportunity Canvas nesta Fase 9 (antes de abrir a geração de ideias do Passo 1) | N12: A cópia do Vol. 1 saiu. O canvas ficou na Fase 9 do Vol. 3. | O12: Corrigido
A13: DA-031 | B13: Exemplo do mapa da v5.0 | C13: 1 | D13: 4636 | E13: Vícios de escrita | F13: Erro de português: exhaustividade | G13: Erro de português: exhaustividade | I13: corrigido em parte | J13: 1 | K13: 3111 | L13: Passo 5: Teste exhaustividade. | N13: Eram 6 ocorrências (Vols. 1, 2 e 3). Resta 1, no passo a passo do MECE do Vol. 1. | O13: Corrigido
... A28: DA-016 | B28: Exemplo do mapa da v5.0 | C28: 1 | D28: 8309 | E28: Vícios de escrita | F28: Vírgula antes do e: Claude, ChatGPT, e Gemini, todos conseguem analisar planilhas | G28: Vírgula antes do e: Claude, ChatGPT, e Gemini, todos conseguem analisar planilhas | I28: corrigido | J28: 1 | K28: 6357 | L28: Claude, ChatGPT e Gemini processam planilhas e arquivos CSV (desde que previamente limpos de dados pessoais identificáveis) em poucos minutos | N28: Parágrafo reescrito no capítulo de IA fundido (Cap. 10). Vírgulas e fragmentos do original sumiram. | O28: Corrigido
A29: DA-144 | B29: Exemplo do mapa da v5.0 | C29: 2 | E29: Consistência entre volumes > Réguas que mudam dentro do volume | F29: Sessões de pesquisa de 8 a 15 ou 15 a 30, e de uma a cinco personas (Vol. 2, Fase 5) | G29: Sessões de pesquisa de 8 a 15 ou 15 a 30, e de uma a cinco personas (Vol. 2, Fase 5) | I29: corrigido | J29: 2 | K29: 1960 | L29: Para a descoberta inicial do problema (Fase 4), quinze a trinta conversas são a referência | N29: A mesma frase diz que a Fase 5 pede oito a quinze sessões longas, então as duas faixas ganharam contexto. As personas ficaram em duas a quatro em toda a fase. | O29: Corrigido
A30: DA-148 | B30: Exemplo do mapa da v5.0 | C30: 2 | E30: Consistência entre volumes > Fases na numeração antiga | F30: Vol. 2: a Fase 5 se chama Fase 4 e chama a Descoberta de Fase 3 em cerca de 15 passagens | G30: Vol. 2: a Fase 5 se chama Fase 4 e chama a Descoberta de Fase 3 em cerca de 15 passagens | I30: corrigido em parte | J30: 2 | K30: 2912 | L30: Use o VPC depois de fazer pesquisa qualitativa real (Fase 4: entrevistas em profundidade, observação em campo, análise de jornada). | N30: A Descoberta não aparece mais como Fase 3 e o critério de saída está certo. Sobra a nota do VPC, que chama a pesquisa e o Dossiê do Usuário de Fase 4. | O30: Corrigido
A31: DA-258 | B31: Exemplo do mapa da v5.0 | C31: 2 | E31: Mapa por volume | F31: Vol. 2: cerca de 45 frases quebradas no Cap. 3 (casos de fracasso) | G31: Vol. 2: cerca de 45 frases quebradas no Cap. 3 (casos de fracasso) | I31: corrigido em parte | J31: 2 | K31: 5944 | L31: os estudos de caso individuais em profundidade estão no Capítulo 19 do Volume 9 | N31: Amostra por busca: frases de uma ou duas palavras no capítulo caíram de 10 para 7, e sumiram Dinheiro acaba. Mercado muda. Concorrente come. Resta Escolher dói. Conferência completa só por releitura. | O31: Corrigido
A32: DA-214 | B32: Exemplo do mapa da v5.0 | C32: 2 | D32: 287 | E32: Conteúdo e precisão > Casos, pessoas e livros | F32: Cinco perguntas atribuídas ao Mom Test, que vêm da palestra de Eric Migicovsky | G32: Cinco perguntas atribuídas ao Mom Test, que vêm da palestra de Eric Migicovsky | I32: corrigido | J32: 2 | K32: 264 | L32: ##### As cinco perguntas de Eric Migicovsky (Y Combinator), compatíveis com o Mom Test (roteiro mínimo) | N32: Atribuição certa. | O32: Corrigido
A33: DA-015 | B33: Exemplo do mapa da v5.0 | C33: 2 | D33: 651 | E33: Vícios de escrita | F33: Dois-pontos virado vírgula: Passo 1, Prepare agenda sem mencionar sua solução. | G33: Dois-pontos virado vírgula: Passo 1, Prepare agenda sem mencionar sua solução. | I33: corrigido | J33: 2 | K33: 586 | L33: Passo 1. Prepare a pauta sem mencionar a solução, listando de cinco a sete perguntas sobre a rotina real do entrevistado diante do problema. | N33: Exemplo corrigido, mas o Passo 1 usa ponto e os Passos 2 e 3 logo abaixo usam dois-pontos. O subtítulo do molde Como rodar na segunda-feira às 9h continua acima. | O33: Corrigido
A34: DA-082 | B34: Exemplo do mapa da v5.0 | C34: 2 | D34: 1458 | E34: Estrutura e navegação > Remissões com numeração antiga | F34: Empathy Map na Fase 3 (descoberta) e Fase 4 (pesquisa), deveria ser Fase 4 e Fase 5 | G34: Empathy Map na Fase 3 (descoberta) e Fase 4 (pesquisa), deveria ser Fase 4 e Fase 5 | I34: corrigido em parte | J34: 2 | K34: 996 | L34: Use também na Fase 4 (pesquisa) para construir o Customer Profile do VPC (Fase 5) com profundidade emocional. | N34: A primeira menção virou Fase 4 (descoberta do problema). A segunda ainda diz Fase 4 (pesquisa), quando a pesquisa é a Fase 5. | O34: Corrigido
A35: DA-043 | B35: Exemplo do mapa da v5.0 | C35: 2 | D35: 2526 | E35: Narrativa > Arquétipos | F35: Camila troca de profissão: cirurgiã-dentista, fisioterapeuta e médica | G35: Camila troca de profissão: cirurgiã-dentista, fisioterapeuta e médica | I35: corrigido em parte | J35: 2 | K35: 1812 | L35: Intrigada, Camila resolveu sentar na recepção por três dias e conversar com os dez pacientes mais fiéis: não sobre fisioterapia, mas sobre o dia em que decidiram agendar. | N35: Camila é dentista em todos os volumes e as cenas de médica (Vol. 3 e Vol. 9) e de fisioterapia do Vol. 4 saíram. Sobrou não sobre fisioterapia na cena da Fase 5, duas linhas depois de clínica odontológica. | O35: Corrigido
A36: DA-064 | B36: Exemplo do mapa da v5.0 | C36: 2 | D36: 2528 | E36: Narrativa > O que funciona e deve ficar | F36: Fio da paciente Dona Helena do Vol. 2 para o Vol. 3 | G36: Fio da paciente Dona Helena do Vol. 2 para o Vol. 3 | I36: persiste | J36: 2 | K36: 3381 | L36: contratado por pacientes de 55 a 70 anos como Dona Helena era voltar a sorrir e mastigar em festas de família sem medo de dor | N36: Qualidade preservada e reforçada: Dona Helena volta no Fechamento da Fase 5 e reaparece no Vol. 3 (l. 1799). | O36: Corrigido
A37: DA-021 | B37: Exemplo do mapa da v5.0 | C37: 2 | D37: 2585 | E37: Vícios de escrita | F37: Fragmento telegráfico: Anote tudo. O que fez. Quanto tempo. Interrupções. | G37: Fragmento telegráfico: Anote tudo. O que fez. Quanto tempo. Interrupções. | I37: corrigido | J37: 2 | K37: 1842 | L37: Anote o que a pessoa fez, quanto tempo levou em cada tarefa, quem a interrompeu, onde ela se irritou e com quem precisou falar no meio do caminho. | N37: Lista picada virou frase com verbo. | O37: Corrigido
A38: DA-017 | B38: Exemplo do mapa da v5.0 | C38: 2 | D38: 2688 | E38: Vícios de escrita | F38: Símbolo por extenso: Triangulação qualitativa mais quantitativa | G38: Símbolo por extenso: Triangulação qualitativa mais quantitativa | I38: corrigido | J38: 2 | K38: 1946 | L38: ##### Triangulação entre entrevistas e survey | N38: O subtítulo foi renomeado e perdeu o mais no lugar do sinal. | O38: Corrigido
A39: DA-212 | B39: Exemplo do mapa da v5.0 | C39: 2 | D39: 3048 | E39: Conteúdo e precisão > Casos, pessoas e livros | F39: Demand-Side Sales 101 é de Bob Moesta e Greg Engle | G39: Demand-Side Sales 101 é de Bob Moesta e Greg Engle | I39: corrigido em parte | J39: 10 | K39: 10450 | L39: Moesta, Bob. *Demand-Side Sales 101: Stop Selling and Help Your Customers Make Progress.* Lioncrest, 2020. | N39: O Vol. 2 (l. 2192) cita Moesta e Engle. A bibliografia omite Engle e o Vol. 7 (l. 1853) liga o livro a Moesta e Chris Spiek. | O39: Corrigido
A40: DA-252 | B40: Exemplo do mapa da v5.0 | C40: 2 | D40: 3097 | E40: Conteúdo e precisão > Conselho arriscado sem ressalva | F40: Pesquisa de campo em clínica com fichas de pacientes à vista e registro em fotos e vídeos, sem LGPD (Vol. 2) | G40: Pesquisa de campo em clínica com fichas de pacientes à vista e registro em fotos e vídeos, sem LGPD (Vol. 2) | I40: corrigido com erro novo | J40: 2 | K40: 2304 | L40: Entre um atendimento e outro na clínica odontológica, perde de 4 a 5 minutos procurando histórico clínico | N40: Entraram consentimento e proibição de fotografar fichas (l. 2304 e 2356). O exemplo virou meio fisioterapia, meio odontologia (l. 2298 e 2304) e remete à LGPD no Capítulo 10 do Vol. 8, que hoje é o Cap. 9. | O40: Corrigido
A41: DA-213 | B41: Exemplo do mapa da v5.0 | C41: 2 | D41: 3649 | E41: Conteúdo e precisão > Casos, pessoas e livros | F41: Moesta como coautor de Competing Against Luck (Vol. 2 e Vol. 9) | G41: Moesta como coautor de Competing Against Luck (Vol. 2 e Vol. 9) | I41: corrigido | J41: 2 | K41: 2785 | L41: *Competing Against Luck* (2016), escrito com Taddy Hall, Karen Dillon e David S. Duncan. | N41: Coautores certos aqui, no Vol. 1 (l. 1248) e na bibliografia (Vol. 10, l. 10368). A cópia do Vol. 9 saiu. | O41: Corrigido
A42: DA-083 | B42: Exemplo do mapa da v5.0 | C42: 2 | D42: 3974 | E42: Estrutura e navegação > Remissões com numeração antiga | F42: Customer Journey Canvas na Fase 4 (pesquisa), deveria ser Fase 5 | G42: Customer Journey Canvas na Fase 4 (pesquisa), deveria ser Fase 5 | I42: corrigido com erro novo | J42: 2 | K42: 3014 | L42: Em momentos de pivô (ver Capítulo 16 do Volume 4), refaça o mapa da jornada antes de qualquer novo investimento operacional. | N42: A fase virou nesta Fase 5. Na mesma linha, a remissão ao pivô usa o número antigo do capítulo: hoje o pivô é o Cap. 11 do Vol. 4, que tem só 11 capítulos. | O42: Corrigido
A43: DA-024 | B43: Exemplo do mapa da v5.0 | C43: 2 | D43: 4482 | E43: Vícios de escrita | F43: Metáfora gasta: a ponta afiada do machado que racha a tora de madeira | G43: Metáfora gasta: a ponta afiada do machado que racha a tora de madeira | I43: corrigido com erro novo | J43: 2 | K43: 3395 | L43: é o seu primeiro pino da fila Na Fase 6, você vai parar de admirar o oceano pela luneta e escolher o único pino de boliche frontal que, quando derrubado com violência cirúrgica | N43: O machado saiu, mas a troca deixou nova antítese (não é o seu teto, é o seu primeiro pino), um ponto faltando antes de Na Fase 6 e manteve a violência cirúrgica e o oceano pela luneta. | O43: Corrigido
... A50: DA-014 | B50: Exemplo do mapa da v5.0 | C50: 2 | D50: 7722 | E50: Vícios de escrita | F50: Frase partida: O nome precisa ser. Memorável. Duas, ou três palavras. | G50: Frase partida: O nome precisa ser. Memorável. Duas, ou três palavras. | I50: corrigido | J50: 2 | K50: 5856 | L50: Um bom nome precisa ser memorável (duas ou três palavras), fácil de usar em conversa, distinto dos rótulos antigos, capaz de sugerir o problema resolvido | N50: O Pilar 2 do Category Design foi reescrito em frase corrida. O capítulo de Category Design foi fundido ao Cap. 2 do Vol. 2. | O50: Corrigido
A51: DA-140 | B51: Exemplo do mapa da v5.0 | C51: 3 | E51: Consistência entre volumes > Réguas que mudam dentro do volume | F51: Amostra de experimento de 30, 80 a 100, 385 ou 500 a 5.000 na Fase 8 | G51: Amostra de experimento de 30, 80 a 100, 385 ou 500 a 5.000 na Fase 8 | I51: corrigido em parte | J51: 3 | K51: 1199 | L51: Embora os 47 visitantes tenham superado a meta mínima de 30, apenas 7 atenderam às ligações | N51: A Fase 8 ganhou tabela de amostra por técnica (l. 1764 a 1773: survey 100 a 500, landing page 500 a 5.000). O exemplo da landing page ainda usa meta mínima de 30 visitantes. | O51: Corrigido
A52: DA-149 | B52: Exemplo do mapa da v5.0 | C52: 3 | E52: Consistência entre volumes > Fases na numeração antiga | F52: Vol. 3: hipóteses como Fase 6 e experimentos como Fase 7, e o Cap. 1 com três mapas de fases, Fases 1B e 2B e PMF na Fase 12 | G52: Vol. 3: hipóteses como Fase 6 e experimentos como Fase 7, e o Cap. 1 com três mapas de fases, Fases 1B e 2B e PMF na Fase 12 | I52: corrigido | J52: 3 | K52: 3700 | L52: Modelo em validação e estruturação pós-PSF (Fase 12 em diante, rumo ao PMF na Fase 13) | N52: Fases 1B e 2B sumiram e hipóteses e experimentos estão nas Fases 7 e 8. Na l. 3644, a confirmação do PMF ainda aparece como da Fase 12 em diante. | O52: Corrigido
A53: DA-260 | B53: Exemplo do mapa da v5.0 | C53: 3 | E53: Mapa por volume | F53: Vol. 3: framework de Gates sem crédito à Antler | G53: Vol. 3: framework de Gates sem crédito à Antler | I53: corrigido em parte | J53: 10 | K53: 10875 | L53: | Framework de Decisão por Gates | Antler, *The Ten Gates* (Adam French, 2025), adaptado para a coleção | | N53: O Índice de Frameworks dá o crédito, mas o Cap. 2 do Vol. 3 (l. 3757 a 4046), onde o scorecard é ensinado, não cita a Antler. | O53: Corrigido
A54: DA-030 | B54: Exemplo do mapa da v5.0 | C54: 3 | D54: 192 | E54: Vícios de escrita | F54: Erro de português: PORQUÊ IMPORTA no molde de hipótese | G54: Erro de português: PORQUÊ IMPORTA no molde de hipótese | I54: corrigido | J54: 3 | K54: 167 | L54: POR QUE IMPORTA (IMPACTO SE FOR FALSA): [qual o impacto no negócio se a premissa cair] | N54: Grafia corrigida no molde e no exemplo preenchido (l. 297). | O54: Corrigido
A55: DA-259 | B55: Exemplo do mapa da v5.0 | C55: 3 | D55: 192 | E55: Mapa por volume | F55: Vol. 3: as ferramentas da Fase 7 praticam o Teatro da Validação que a fase condena (falta critério de descarte) | G55: Vol. 3: as ferramentas da Fase 7 praticam o Teatro da Validação que a fase condena (falta critério de descarte) | I55: corrigido | J55: 3 | K55: 169 | L55: VAMOS DESCARTAR SE: [critério numérico de refutação] | N55: O molde de hipótese ganhou campo de descarte e zona cinzenta, e ponto de corte ou critério de descarte aparece 12 vezes no Vol. 3 (eram 2). | O55: Corrigido
A56: DA-087 | B56: Exemplo do mapa da v5.0 | C56: 3 | D56: 1279 | E56: Estrutura e navegação > Remissões com numeração antiga | F56: Hypothesis Canvas na Fase 6, deveria ser Fase 7 (cópia do Vol. 3) | G56: Hypothesis Canvas na Fase 6, deveria ser Fase 7 (cópia do Vol. 3) | I56: corrigido | J56: 3 | K56: 705 | L56: Use o Hypothesis Canvas na Fase 7 (formulação rigorosa de hipóteses) como artefato central | N56: Número certo. | O56: Corrigido
A57: DA-088 | B57: Exemplo do mapa da v5.0 | C57: 3 | D57: 1453 | E57: Estrutura e navegação > Remissões com numeração antiga | F57: Banco de Hipóteses: ao iniciar a Fase 6 (priorização), deveria ser Fase 7 | G57: Banco de Hipóteses: ao iniciar a Fase 6 (priorização), deveria ser Fase 7 | I57: corrigido | J57: 3 | K57: 765 | L57: **Quando usar:** no início da Fase 7 (formulação e priorização de hipóteses) | N57: Número certo. | O57: Corrigido
