Workbook

Sheet Leia-me
A1: IGNIÇÃO v5.0: achados da revisão
A2: Revisão completa dos 10 volumes feita em outubro de 2026. Cada linha da aba Achados é um problema marcado por um revisor, com a linha do arquivo .md do volume, o trecho citado e a correção sugerida.
A4: Abas
A5: Achados: os 5.621 achados, um por linha, em ordem de volume e linha. Use os filtros do cabeçalho para ver um volume, uma categoria ou só a gravidade alta.
A6: Checagem: as afirmações conferidas na web contra lei, norma, documento oficial da empresa ou imprensa de referência, com o veredito, o que vale em outubro de 2026 e o link da fonte.
A7: Resumo: contagens por volume, categoria e veredito, calculadas por fórmula a partir das outras abas. Mudam sozinhas quando você atualiza o Status.
A9: Como usar
A10: A coluna Status (fundo amarelo) é a única feita para editar. Valores aceitos: Pendente, Em revisão, Corrigido, Descartado. Todas começam como Pendente.
A11: Gravidade alta: erro factual, frase corrompida, contradição, conselho arriscado, promessa da edição quebrada ou passagem que um leitor exigente usaria para desacreditar o livro. Média: vício recorrente que cansa ou enfraquece o texto. Baixa: polimento.
A12: Pede checagem = sim marca afirmações que o revisor não conseguiu confirmar só com o texto. Quando a coluna Checagem na web está vazia, a afirmação ainda não foi conferida.
A13: Os revisores também erram: na checagem, 5 suspeitas se mostraram certas no livro. Outras 128 saíram parcialmente certas, com um detalhe que ainda pede conserto. Nenhuma correção de lei, número ou caso real deve entrar no livro sem a fonte primária aberta.
A14: Linha é a linha do arquivo .md do volume na versão revisada. Se o arquivo mudar, busque pelo trecho citado.
... A17: Categorias
A18: Código | B18: Grupo | C18: O que marca
A19: E1 | B19: Escrita | C19: Antítese "não é X, é Y"
A20: E2 | B20: Escrita | C20: Fragmento telegráfico
A21: E3 | B21: Escrita | C21: Adjetivo inflado ou intensificador
A22: E4 | B22: Escrita | C22: Metadiscurso, abertura enfática, rótulo
A23: E5 | B23: Escrita | C23: Pergunta retórica com resposta imediata
A24: E6 | B24: Escrita | C24: Clichê ou metáfora gasta
A25: E7 | B25: Escrita | C25: Anglicismo ou mistura founder/fundador
A26: E8 | B26: Escrita | C26: Glosa repetida entre parênteses
A27: E9 | B27: Escrita | C27: Erro gramatical ou frase corrompida
A28: E10 | B28: Escrita | C28: Repetição, redundância, enchimento
A29: E11 | B29: Escrita | C29: Registro inconsistente ou tom de coach
... A53: C7 | B53: Conteúdo | C53: Conselho arriscado sem ressalva

Sheet Resumo
A1: Resumo dos achados
A2: Tudo nesta aba é fórmula sobre as abas Achados e Checagem.
A4: Achados por volume e gravidade
A5: Volume | B5: Alta | C5: Média | D5: Baixa | E5: Total | F5: Corrigidos | G5: % corrigido
A6: 1 | B6: =COUNTIFS(Achados!$B$2:$B$5622,$A6,Achados!$G$2:$G$5622,"alta") -> 150 | C6: =COUNTIFS(Achados!$B$2:$B$5622,$A6,Achados!$G$2:$G$5622,"média") -> 384 | D6: =COUNTIFS(Achados!$B$2:$B$5622,$A6,Achados!$G$2:$G$5622,"baixa") -> 18 | E6: =SUM(B6:D6) -> 552 | F6: =COUNTIFS(Achados!$B$2:$B$5622,$A6,Achados!$R$2:$R$5622,"Corrigido") -> 0 | G6: =IF(E6=0,0,F6/E6) -> 0
A7: 2 | B7: =COUNTIFS(Achados!$B$2:$B$5622,$A7,Achados!$G$2:$G$5622,"alta") -> 124 | C7: =COUNTIFS(Achados!$B$2:$B$5622,$A7,Achados!$G$2:$G$5622,"média") -> 207 | D7: =COUNTIFS(Achados!$B$2:$B$5622,$A7,Achados!$G$2:$G$5622,"baixa") -> 35 | E7: =SUM(B7:D7) -> 366 | F7: =COUNTIFS(Achados!$B$2:$B$5622,$A7,Achados!$R$2:$R$5622,"Corrigido") -> 0 | G7: =IF(E7=0,0,F7/E7) -> 0
A8: 3 | B8: =COUNTIFS(Achados!$B$2:$B$5622,$A8,Achados!$G$2:$G$5622,"alta") -> 188 | C8: =COUNTIFS(Achados!$B$2:$B$5622,$A8,Achados!$G$2:$G$5622,"média") -> 255 | D8: =COUNTIFS(Achados!$B$2:$B$5622,$A8,Achados!$G$2:$G$5622,"baixa") -> 14 | E8: =SUM(B8:D8) -> 457 | F8: =COUNTIFS(Achados!$B$2:$B$5622,$A8,Achados!$R$2:$R$5622,"Corrigido") -> 0 | G8: =IF(E8=0,0,F8/E8) -> 0
A9: 4 | B9: =COUNTIFS(Achados!$B$2:$B$5622,$A9,Achados!$G$2:$G$5622,"alta") -> 190 | C9: =COUNTIFS(Achados!$B$2:$B$5622,$A9,Achados!$G$2:$G$5622,"média") -> 325 | D9: =COUNTIFS(Achados!$B$2:$B$5622,$A9,Achados!$G$2:$G$5622,"baixa") -> 25 | E9: =SUM(B9:D9) -> 540 | F9: =COUNTIFS(Achados!$B$2:$B$5622,$A9,Achados!$R$2:$R$5622,"Corrigido") -> 0 | G9: =IF(E9=0,0,F9/E9) -> 0
A10: 5 | B10: =COUNTIFS(Achados!$B$2:$B$5622,$A10,Achados!$G$2:$G$5622,"alta") -> 224 | C10: =COUNTIFS(Achados!$B$2:$B$5622,$A10,Achados!$G$2:$G$5622,"média") -> 291 | D10: =COUNTIFS(Achados!$B$2:$B$5622,$A10,Achados!$G$2:$G$5622,"baixa") -> 30 | E10: =SUM(B10:D10) -> 545 | F10: =COUNTIFS(Achados!$B$2:$B$5622,$A10,Achados!$R$2:$R$5622,"Corrigido") -> 0 | G10: =IF(E10=0,0,F10/E10) -> 0
A11: 6 | B11: =COUNTIFS(Achados!$B$2:$B$5622,$A11,Achados!$G$2:$G$5622,"alta") -> 228 | C11: =COUNTIFS(Achados!$B$2:$B$5622,$A11,Achados!$G$2:$G$5622,"média") -> 384 | D11: =COUNTIFS(Achados!$B$2:$B$5622,$A11,Achados!$G$2:$G$5622,"baixa") -> 19 | E11: =SUM(B11:D11) -> 631 | F11: =COUNTIFS(Achados!$B$2:$B$5622,$A11,Achados!$R$2:$R$5622,"Corrigido") -> 0 | G11: =IF(E11=0,0,F11/E11) -> 0
A12: 7 | B12: =COUNTIFS(Achados!$B$2:$B$5622,$A12,Achados!$G$2:$G$5622,"alta") -> 115 | C12: =COUNTIFS(Achados!$B$2:$B$5622,$A12,Achados!$G$2:$G$5622,"média") -> 231 | D12: =COUNTIFS(Achados!$B$2:$B$5622,$A12,Achados!$G$2:$G$5622,"baixa") -> 17 | E12: =SUM(B12:D12) -> 363 | F12: =COUNTIFS(Achados!$B$2:$B$5622,$A12,Achados!$R$2:$R$5622,"Corrigido") -> 0 | G12: =IF(E12=0,0,F12/E12) -> 0
A13: 8 | B13: =COUNTIFS(Achados!$B$2:$B$5622,$A13,Achados!$G$2:$G$5622,"alta") -> 170 | C13: =COUNTIFS(Achados!$B$2:$B$5622,$A13,Achados!$G$2:$G$5622,"média") -> 196 | D13: =COUNTIFS(Achados!$B$2:$B$5622,$A13,Achados!$G$2:$G$5622,"baixa") -> 1 | E13: =SUM(B13:D13) -> 367 | F13: =COUNTIFS(Achados!$B$2:$B$5622,$A13,Achados!$R$2:$R$5622,"Corrigido") -> 0 | G13: =IF(E13=0,0,F13/E13) -> 0
A14: 9 | B14: =COUNTIFS(Achados!$B$2:$B$5622,$A14,Achados!$G$2:$G$5622,"alta") -> 255 | C14: =COUNTIFS(Achados!$B$2:$B$5622,$A14,Achados!$G$2:$G$5622,"média") -> 375 | D14: =COUNTIFS(Achados!$B$2:$B$5622,$A14,Achados!$G$2:$G$5622,"baixa") -> 8 | E14: =SUM(B14:D14) -> 638 | F14: =COUNTIFS(Achados!$B$2:$B$5622,$A14,Achados!$R$2:$R$5622,"Corrigido") -> 0 | G14: =IF(E14=0,0,F14/E14) -> 0
A15: 10 | B15: =COUNTIFS(Achados!$B$2:$B$5622,$A15,Achados!$G$2:$G$5622,"alta") -> 325 | C15: =COUNTIFS(Achados!$B$2:$B$5622,$A15,Achados!$G$2:$G$5622,"média") -> 714 | D15: =COUNTIFS(Achados!$B$2:$B$5622,$A15,Achados!$G$2:$G$5622,"baixa") -> 123 | E15: =SUM(B15:D15) -> 1162 | F15: =COUNTIFS(Achados!$B$2:$B$5622,$A15,Achados!$R$2:$R$5622,"Corrigido") -> 0 | G15: =IF(E15=0,0,F15/E15) -> 0
A16: Total | B16: =SUM(B6:B15) -> 1969 | C16: =SUM(C6:C15) -> 3362 | D16: =SUM(D6:D15) -> 290 | E16: =SUM(E6:E15) -> 5621 | F16: =SUM(F6:F15) -> 0 | G16: =IF(E16=0,0,F16/E16) -> 0
A17: Volume é o arquivo onde o achado está. Aparato e arquétipos entram no volume da linha citada.
A19: Checagem na web por veredito
A20: Veredito | B20: Afirmações | C20: % do checado
A21: erro confirmado | B21: =COUNTIF(Checagem!$F$2:$F$494,$A21) -> 245 | C21: =IF($B$27=0,0,B21/$B$27) -> 0.4969574
A22: desatualizado | B22: =COUNTIF(Checagem!$F$2:$F$494,$A22) -> 85 | C22: =IF($B$27=0,0,B22/$B$27) -> 0.17241379
A23: parcialmente certo | B23: =COUNTIF(Checagem!$F$2:$F$494,$A23) -> 128 | C23: =IF($B$27=0,0,B23/$B$27) -> 0.25963489
A24: correto no livro | B24: =COUNTIF(Checagem!$F$2:$F$494,$A24) -> 5 | C24: =IF($B$27=0,0,B24/$B$27) -> 0.010141988
A25: não verificável | B25: =COUNTIF(Checagem!$F$2:$F$494,$A25) -> 23 | C25: =IF($B$27=0,0,B25/$B$27) -> 0.046653144
A26: não checada | B26: =COUNTIF(Checagem!$F$2:$F$494,$A26) -> 7 | C26: =IF($B$27=0,0,B26/$B$27) -> 0.014198783
A27: Total | B27: =SUM(B21:B26) -> 493 | C27: =IF($B$27=0,0,B27/$B$27) -> 1
A30: Achados por categoria
A31: Código | B31: Categoria | C31: Grupo | D31: Total | E31: Alta
A32: E1 | B32: Antítese "não é X, é Y" | C32: Escrita | D32: =COUNTIF(Achados!$E$2:$E$5622,$A32) -> 77 | E32: =COUNTIFS(Achados!$E$2:$E$5622,$A32,Achados!$G$2:$G$5622,"alta") -> 0
A33: E2 | B33: Fragmento telegráfico | C33: Escrita | D33: =COUNTIF(Achados!$E$2:$E$5622,$A33) -> 73 | E33: =COUNTIFS(Achados!$E$2:$E$5622,$A33,Achados!$G$2:$G$5622,"alta") -> 8
A34: E3 | B34: Adjetivo inflado ou intensificador | C34: Escrita | D34: =COUNTIF(Achados!$E$2:$E$5622,$A34) -> 70 | E34: =COUNTIFS(Achados!$E$2:$E$5622,$A34,Achados!$G$2:$G$5622,"alta") -> 0
A35: E4 | B35: Metadiscurso, abertura enfática, rótulo | C35: Escrita | D35: =COUNTIF(Achados!$E$2:$E$5622,$A35) -> 34 | E35: =COUNTIFS(Achados!$E$2:$E$5622,$A35,Achados!$G$2:$G$5622,"alta") -> 0
A36: E5 | B36: Pergunta retórica com resposta imediata | C36: Escrita | D36: =COUNTIF(Achados!$E$2:$E$5622,$A36) -> 7 | E36: =COUNTIFS(Achados!$E$2:$E$5622,$A36,Achados!$G$2:$G$5622,"alta") -> 0
A37: E6 | B37: Clichê ou metáfora gasta | C37: Escrita | D37: =COUNTIF(Achados!$E$2:$E$5622,$A37) -> 39 | E37: =COUNTIFS(Achados!$E$2:$E$5622,$A37,Achados!$G$2:$G$5622,"alta") -> 1
A38: E7 | B38: Anglicismo ou mistura founder/fundador | C38: Escrita | D38: =COUNTIF(Achados!$E$2:$E$5622,$A38) -> 141 | E38: =COUNTIFS(Achados!$E$2:$E$5622,$A38,Achados!$G$2:$G$5622,"alta") -> 7
A39: E8 | B39: Glosa repetida entre parênteses | C39: Escrita | D39: =COUNTIF(Achados!$E$2:$E$5622,$A39) -> 51 | E39: =COUNTIFS(Achados!$E$2:$E$5622,$A39,Achados!$G$2:$G$5622,"alta") -> 1
A40: E9 | B40: Erro gramatical ou frase corrompida | C40: Escrita | D40: =COUNTIF(Achados!$E$2:$E$5622,$A40) -> 555 | E40: =COUNTIFS(Achados!$E$2:$E$5622,$A40,Achados!$G$2:$G$5622,"alta") -> 199
A41: E10 | B41: Repetição, redundância, enchimento | C41: Escrita | D41: =COUNTIF(Achados!$E$2:$E$5622,$A41) -> 52 | E41: =COUNTIFS(Achados!$E$2:$E$5622,$A41,Achados!$G$2:$G$5622,"alta") -> 1
A42: E11 | B42: Registro inconsistente ou tom de coach | C42: Escrita | D42: =COUNTIF(Achados!$E$2:$E$5622,$A42) -> 18 | E42: =COUNTIFS(Achados!$E$2:$E$5622,$A42,Achados!$G$2:$G$5622,"alta") -> 2
A43: E12 | B43: Frase longa demais | C43: Escrita | D43: =COUNTIF(Achados!$E$2:$E$5622,$A43) -> 38 | E43: =COUNTIFS(Achados!$E$2:$E$5622,$A43,Achados!$G$2:$G$5622,"alta") -> 1
... A66: C7 | B66: Conselho arriscado sem ressalva | C66: Conteúdo | D66: =COUNTIF(Achados!$E$2:$E$5622,$A66) -> 194 | E66: =COUNTIFS(Achados!$E$2:$E$5622,$A66,Achados!$G$2:$G$5622,"alta") -> 83
...

Sheet Achados
A1: Nº | B1: Volume | C1: Linha | D1: Unidade | E1: Código | F1: Categoria | G1: Gravidade | H1: Trecho citado | I1: Problema | J1: Sugestão | K1: Recorrente | L1: Ocorrências estimadas | M1: Pede checagem | N1: Checagem na web | O1: O que vale em out/2026 | P1: Fonte da checagem | Q1: Origem | R1: Pendente
A2: 1 | B2: 1 | C2: 24 | D2: Nota do autor | E2: E3 | F2: Adjetivo inflado ou intensificador | G2: média | H2: e da solidão brutal de quem carrega o CPF na linha de tiro | I2: Adjetivos da lista de cortes concentrados na Nota: 'solidão brutal' (24), 'foco obsessivo' (32), 'negócios silenciosos' (35), 'armadilhas invisíveis' (38), além do rótulo 'Mais importante:' (35). | J2: Na 24: "e da solidão de quem responde com o próprio CPF". Na 35, abrir direto ("Você não fará esta travessia sozinho") e trocar "negócios silenciosos do interior" por "negócios do interior que nunca saíram no jornal". | K2: sim | L2: 5 | M2: não | Q2: Revisor de trecho | R2: Corrigido
A3: 2 | B3: 1 | C3: 24 | D3: Nota do autor | E3: C2 | F3: Informação possivelmente desatualizada | G3: média | H3: de 5.570 legislações municipais de nota fiscal | I3: Com a reforma tributária, a NFS-e de padrão nacional deve valer para os municípios desde 2026. Falar em 5.570 legislações de nota fiscal pode soar datado em outubro de 2026. | J3: Verificar a situação da NFS-e nacional e reescrever, por exemplo: "de um ISS que ainda muda de cidade para cidade enquanto a reforma tributária não conclui a transição". | K3: não | L3: 1 | M3: sim | Q3: Revisor de trecho | R3: Corrigido
A4: 3 | B4: 1 | C4: 29 | D4: Nota do autor | E4: E11 | F4: Registro inconsistente ou tom de coach | G4: baixa | H4: - De **Michael Gerber** (*O Mito do Empreendedor*), trouxemos a conversa direta, olho no olho | I4: A Nota alterna 'eu' (resisti, cometi, escrevi) e 'nós' (trouxemos) para o mesmo autor. E a passagem pessoal sobre influências virou lista com marcadores. | J4: Manter a primeira pessoa do singular e passar a lista a dois parágrafos de prosa: o que cada autor mudou na prática do autor, com um caso próprio. | K4: não | L4: 1 | M4: não | Q4: Revisor de trecho | R4: Corrigido
A5: 4 | B5: 1 | C5: 35 | D5: Nota do autor | E5: N3 | F5: Arquétipo inconsistente, decorativo ou ausente | G5: alta | H5: você acompanhará ao longo dos volumes a jornada viva de | I5: Em 148 das 149 unidades que abrem com arquétipo, ele some antes da linha 17 e não volta no corpo, no Espelho, no Ritual ou na Oficina. Só Dona Helena (2:2528, 3:3167) liga duas cenas. | J5: Dar ao arquétipo da abertura uma volta no fecho de cada unidade: um parágrafo antes do Espelho com o desfecho da cena e os números dela aplicados à ferramenta, mais uma linha de memória por volume ("no Vol. 1, Lucas..."). | K5: sim | L5: 148 | M5: não | Q5: Leitura cruzada dos arquétipos | R5: Corrigido
A6: 5 | B6: 1 | C6: 38 | D6: Nota do autor | E6: N9 | F6: Título que promete o que o corpo não entrega | G6: alta | H6: 1. **A Narrativa de Trincheira (Atos 1 a 4):** abrimos sempre no meio da tensão real | I6: A Nota promete narrativa em 'Atos 1 a 4', mas nenhuma fase ou capítulo do volume marca atos. O leitor procura a estrutura anunciada e não a encontra. | J6: Cortar "(Atos 1 a 4)" ou marcar os atos nas fases. Se a estrutura real é cena, diagnóstico, armadilhas, Espelho e Ritual, descrever assim. | K6: não | L6: 1 | M6: não | Q6: Revisor de trecho | R6: Corrigido
A7: 6 | B7: 1 | C7: 43 | D7: Nota do autor | E7: E6 | F7: Clichê ou metáfora gasta | G7: média | H7: Boa subida — e nos vemos na trincheira. | I7: Metáforas misturadas na Nota: trincheira, cicatriz e linha de tiro (guerra) convivem com subida, topo da montanha e pedra (escalada). A imagem central da obra se dilui. | J7: Escolher uma imagem. Se for o caderno de campo da linha 22, manter o caderno aberto às onze da noite e cortar subida, pedra e a despedida na trincheira. Fechar com uma frase sobre como usar o livro. | K7: sim | L7: 7 | M7: não | Q7: Revisor de trecho | R7: Corrigido
A8: 7 | B8: 1 | C8: 76 | D8: Os 4 Fundadores | E8: N3 | F8: Arquétipo inconsistente, decorativo ou ausente | G8: média | H8: você acompanhará de perto a evolução, os tropeços, as brigas societárias, os pivôs e as vitórias de | I8: Distribuição torta: Lucas e Marina abrem 62 de 149 unidades (42%), Camila 24 (16%). Henrique não abre fase depois do Vol. 4. Rafael e Bia abrem 3 de 23 unidades nos Vols. 1 e 2. | J8: Trocar 8 a 10 aberturas de Lucas e Marina nos Vols. 4 a 6 por outros arquétipos (ex.: Vol. 5, Cap. 11 com a crise de caixa de Rafael e Bia, Vol. 4, Cap. 9 com o medo de cobrar de Camila) e dar a Henrique uma abertura de fase entre 14 e 20. | K8: não | L8: 1 | M8: não | Q8: Leitura cruzada dos arquétipos | R8: Corrigido
A9: 8 | B9: 1 | C9: 80 | D9: Os 4 Fundadores | E9: N3 | F9: Arquétipo inconsistente, decorativo ou ausente | G9: média | H9: Descobrem o poder do *Vertical SaaS + Embedded Finance* | I9: O produto nunca fica vertical: é tesouraria para qualquer empresa média (2:7658, 4:6905, 6:5971). O crédito embutido só aparece no agente de 8:4811. | J9: Ou trocar a promessa por "tesouraria preditiva com crédito embutido", ou verticalizar numa cena dos Vols. 5 ou 6 (foco em distribuidores, o que casa com a distribuidora de 2:90 e a varejista de 8:2396). | K9: não | L9: 1 | M9: não | Q9: Leitura cruzada dos arquétipos | R9: Corrigido
A10: 9 | B10: 1 | C10: 81 | D10: Os 4 Fundadores | E10: N3 | F10: Arquétipo inconsistente, decorativo ou ausente | G10: média | H10: Mistura contas de casa com o CNPJ, compra equipamento caro por impulso (*custo afundado*) e tem medo de cobrar o que vale | I10: Só o custo afundado vira cena (1:6161). Contas misturadas e medo de cobrar não aparecem nas 29 cenas de Camila. Em 4:5684 ela já cobra R$ 480 por sessão sem conflito. | J10: Abrir o Vol. 4, Cap. 9 (preço) com Camila cobrando abaixo da tabela por vergonha e pôr as contas misturadas na cena de 5:1776: a escola dos filhos paga com o PIX da clínica explica parte do lucro que não vira caixa. | K10: não | L10: 1 | M10: não | Q10: Leitura cruzada dos arquétipos | R10: Corrigido
A11: 10 | B11: 1 | C11: 82 | D11: Os 4 Fundadores | E11: C5 | F11: Contradição interna | G11: baixa | H11: Aprende a vender para comitês complexos de 7 decisores | I11: O capítulo de vendas complexas (Vol. 6, Cap. 2) organiza o comitê em 6 cadeiras. E o fomento de Henrique (5:8061) é Finep e EMBRAPII, sem o BNDES prometido. | J11: "comitês complexos de seis cadeiras" e "subvenção Finep e EMBRAPII", ou acrescentar o BNDES na cena de 5:8061. | K11: não | L11: 1 | M11: não | Q11: Leitura cruzada dos arquétipos | R11: Corrigido
A12: 11 | B12: 1 | C12: 83 | D12: Os 4 Fundadores | E12: C5 | F12: Contradição interna | G12: média | H12: **Rafael** (27, criativo de marketing no Recife) e **Bia** (28, engenheira de produção em Goiânia | I12: A bíblia põe cada sócio numa cidade e não diz onde fica a empresa. As cenas alternam Recife (14), Goiânia (5) e as duas (5), com os dois juntos na cozinha, na sala e no escritório. | J12: Completar a tabela: "sede e marketing em Recife (Rafael), centro de distribuição e operações em Goiânia (Bia)". Nas cenas a dois, dizer quem viajou. | K12: não | L12: 1 | M12: não | Q12: Leitura cruzada dos arquétipos | R12: Corrigido
A13: 12 | B13: 1 | C13: 83 | D13: Os 4 Fundadores | E13: N3 | F13: Arquétipo inconsistente, decorativo ou ausente | G13: média | H13: sofrem com ruptura de estoque e descobrem o peso da cadeia logística e tributária brasileira | I13: Nenhuma das 29 cenas de Rafael e Bia mostra ruptura de estoque, embora Bia seja "obcecada por estoque". A marca omnichannel prometida também não chega (9:112). | J13: Usar Rafael e Bia na abertura de um capítulo de operação do Vol. 4 ou 7: a Black Friday que vende o que não há no centro de distribuição de Goiânia, com o custo da ruptura na conta. | K13: não | L13: 1 | M13: não | Q13: Leitura cruzada dos arquétipos | R13: Corrigido
... A50: 49 | B50: 1 | C50: 436 | D50: FASE 0 | E50: E9 | F50: Erro gramatical ou frase corrompida | G50: alta | H50: o [[#Canvas: Team Canvas (Alex Ivanov, 2015)|Canvas: Team Canvas (Alex Ivanov, 2015)]] (Alex Ivanov, 2015) é o template | I50: A substituição mecânica duplicou autor e ano e gerou a frase 'Canvas: Team Canvas (Alex Ivanov, 2015) (Fase 0) também é referenciado'. O callout de uso prático ficou ilegível. | J50: Reescrever: "Quando o time tem dois ou mais cofundadores, use o Team Canvas (Alex Ivanov, 2015) para alinhar pessoas, objetivos, papéis, valores, forças e regras antes do primeiro conflito." Cortar a frase seguinte. | K50: não | L50: 1 | M50: não | Q50: Revisor de trecho | R50: Corrigido
A51: 50 | B51: 1 | C51: 448 | D51: FASE 0 | E51: C3 | F51: Erro factual provável | G51: alta | H51: O terceiro perfil é o especialista de domínio, ou hipster. | I51: Na tríade conhecida hacker, hustler e hipster, o hipster é o designer. O texto redefine o termo e depois cria o design como quarto perfil. Quem conhece a tríade desconfia do resto. | J51: Manter a tríade original, com o hipster como design, e tratar o especialista do setor à parte. Ou largar os apelidos e falar em técnico, comercial e especialista do setor. | K51: não | L51: 1 | M51: não | N51: não checada | O51: Não checada nesta rodada. | Q51: Revisor de trecho | R51: Corrigido
A52: 51 | B52: 1 | C52: 474 | D52: FASE 0 | E52: N7 | F52: Autoridade forçada ou atribuição duvidosa | G52: média | H52: A formalização vem do modelo Antler para founding teams. | I52: Atribuição sem fonte. Não há referência pública conhecida de um 'modelo Antler' com cinco perfis fundadores. Parece autoridade emprestada. | J52: Verificar. Sem fonte, assumir como proposta do autor: "Em produtos complexos, a meu ver, os três perfis viram cinco." | K52: não | L52: 1 | M52: sim | Q52: Revisor de trecho | R52: Corrigido
A53: 52 | B53: 1 | C53: 480 | D53: FASE 0 | E53: E9 | F53: Erro gramatical ou frase corrompida | G53: média | H53: O padrão de três (Técnico mais Comercial mais Domínio) serve estágios pré-Série A. | I53: Troca mecânica de símbolos por palavras: '+' virou 'mais' (480, 657, 1549) e 'vs.' virou 'contra' ('gastar contra poupar', 493, 'Como trata garçom contra como trata CEO', 513). | J53: Reescrever: "O trio técnico, comercial e de domínio basta antes da Série A" e "Como trata o garçom e como trata o CEO". Buscar " mais " e " contra " entre substantivos em todo o volume. | K53: sim | L53: 6 | M53: não | Q53: Revisor de trecho | R53: Corrigido
A54: 53 | B54: 1 | C54: 502 | D54: FASE 0 | E54: N7 | F54: Autoridade forçada ou atribuição duvidosa | G54: média | H54: Use estruturas como o "Relationship Red Flags" do Founder Institute ou o founder compatibility interview do Nathan Rose. | I54: Duas referências que o leitor não vai achar: não há registro conhecido desses roteiros com esses nomes. Na 504, as opções 'primeira, segunda, terceira' viram 'opções A ou B'. | J54: Verificar. Sem fonte, trocar por um roteiro próprio de dez perguntas no Caderno de Campo e uniformizar a numeração das opções. | K54: não | L54: 1 | M54: sim | Q54: Revisor de trecho | R54: Corrigido
A55: 54 | B55: 1 | C55: 512 | D55: FASE 0 | E55: E9 | F55: Erro gramatical ou frase corrompida | G55: média | H55: 5. Discordância em regime patrimonial. Um quer muito, outro quer médio. | I55: O termo 'regime patrimonial' vem do direito de família (regime de bens). O sentido aqui é ambição de patrimônio ou de tamanho da empresa. | J55: Reescrever: "5. Ambição desalinhada. Um quer construir algo enorme, o outro quer uma empresa de ritmo sustentável." | K55: não | L55: 1 | M55: não | Q55: Revisor de trecho | R55: Corrigido
A56: 55 | B56: 1 | C56: 524 | D56: FASE 0 | E56: C5 | F56: Contradição interna | G56: média | H56: - [ ] Trabalhamos juntos em projeto com prazo e entrega por pelo menos 4 semanas. | I56: Três prazos para testar o sócio: três a seis meses (500), pelo menos quatro semanas (524), quatro a oito semanas com 'seis semanas' na mesma linha (558). | J56: Fixar piso e ideal, "no mínimo seis semanas, idealmente três meses", e repetir igual nos três pontos. | K56: não | L56: 1 | M56: não | Q56: Revisor de trecho | R56: Corrigido
A57: 56 | B57: 1 | C57: 535 | D57: FASE 0 | E57: C7 | F57: Conselho arriscado sem ressalva | G57: média | H57: O FAST (Founder Advisor Standard Template, criado por Adeo Ressi no Founder Institute em 2011), contrato padrão para formalizar a relação com advisors | I57: FAST é modelo americano. Numa LTDA, dar de 0,1% a 1% a advisor (578) exige alteração contratual ou opção de compra, e vesting de quotas pede contrato próprio. Falta a ressalva. | J57: Acrescentar: "No Brasil a maioria das startups nasce LTDA. Participação para advisor ou vesting entre sócios pede contrato de opção ou cláusula no acordo de quotistas. Valide com advogado." Alinhar a faixa ao Cap. 13 (0,1% a 0,5%). | K57: não | L57: 1 | M57: não | Q57: Revisor de trecho | R57: Corrigido
A58: 57 | B58: 1 | C58: 542 | D58: FASE 0 | E58: S5 | F58: Duplicação com outro capítulo ou volume | G58: média | H58: Sobre equity split, três princípios. Divisão cinquenta-cinquenta exata é comum mas gera conflito em decisões empatadas. | I58: Sobrepõe o Cap. 2 do volume ('As bombas-relógio societárias: 50/50 sem desempate, falta de vesting', linha 5771). E o vesting 'agressivo' da 537 vira 'padrão' aqui. | J58: Deixar na Fase 0 a decisão de ter ou não sócio e o teste antes de fundar. Equity, 50/50 e vesting ficam no Cap. 2, com remissão de uma linha. | K58: não | L58: 1 | M58: não | Q58: Revisor de trecho | R58: Corrigido
A59: 58 | B59: 1 | C59: 548 | D59: FASE 0 | E59: S7 | F59: Artefato de formatação | G59: média | H59: Capítulo 11 (IA COMO CO-PILOTO DO FUNDADOR (2026)) | I59: Remissões geradas por script com o título em caixa alta entre parênteses, às vezes aninhados ou dobrados ('Capítulo 12 (...) (Vol. 6)'). São 23 no trecho e pesam na leitura. | J59: Padrão curto: "o Capítulo 11 (IA como copiloto)" ou só "o Capítulo 11", com o link no número. | K59: sim | L59: 23 | M59: não | Q59: Revisor de trecho | R59: Corrigido
A60: 59 | B60: 1 | C60: 557 | D60: FASE 0 | E60: C2 | F60: Informação possivelmente desatualizada | G60: média | H60: **Antler** opera no Brasil, com programa residencial intensivo em que squads se formam ao longo de algumas semanas. | I60: Lista que muda rápido: presença da Antler no Brasil, fim da On Deck, o que é 'BU21', Distrito e ACE hoje. Na 559, Fenabrave não é evento de fundadores e o Startup Weekend pode ter acabado. | J60: Verificar item por item, datar a lista ("programas ativos em 2026") e cortar o que não se confirmar, como "BU21" e Fenabrave. | K60: não | L60: 1 | M60: sim | Q60: Revisor de trecho | R60: Corrigido
A61: 60 | B61: 1 | C61: 579 | D61: FASE 0 | E61: C5 | F61: Contradição interna | G61: média | H61: - [ ] Mapeei pessoas afetadas pela decisão (cônjuge, pais, dependentes) e tenho concordância explícita delas, documentada em um parágrafo. | I61: A trava exige concordância explícita de cônjuge e pais. O fluxograma aceita família neutra e o sinal 7 só barra oposição forte. Os pais como condição aparecem só aqui. | J61: Reescrever: "...e tive a conversa estruturada com elas, com apoio ou neutralidade registrados em um parágrafo. Oposição forte aciona o sinal 7." | K61: não | L61: 1 | M61: não | Q61: Revisor de trecho | R61: Corrigido
A62: 61 | B62: 1 | C62: 596 | D62: FASE 0 | E62: N9 | F62: Título que promete o que o corpo não entrega | G62: média | H62: ### Onde os otimistas tropeçam: otimismo financeiro, sociedade de bar e fuga disfarçada | I62: O título promete 'fuga disfarçada', mas o corpo traz 'subestimar impacto psicológico'. O resumo operacional (660 a 663) lista um terceiro trio de armadilhas. | J62: Unificar as três armadilhas da fase e usar as mesmas no título, no corpo e no resumo. | K62: não | L62: 1 | M62: não | Q62: Revisor de trecho | R62: Corrigido
A63: 62 | B63: 1 | C63: 611 | D63: FASE 0 | E63: S6 | F63: Seção desproporcional ou fora de lugar | G63: média | H63: ### CASO BRASILEIRO — Nubank: do reconhecimento da dor à confirmação de modelo | I63: O único caso real da fase fala de PMF, fila, NPS, rodadas e IPO, e apresenta os sócios três vezes (615, 617, 621). Nada sobre runway pessoal, família ou motivação, o tema da Fase 0. | J63: Reduzir o Nubank a um parágrafo sobre o "por que eu" de cada sócio e trocar o caso por um de preparação pessoal (fundador que montou reserva antes de sair). Levar PMF e IPO à Fase 13. | K63: não | L63: 1 | M63: não | Q63: Revisor de trecho | R63: Corrigido
... A74: 73 | B74: 1 | C74: 730 | D74: FASE 0 | E74: E9 | F74: Erro gramatical ou frase corrompida | G74: média | H74: Collins descreve companies que levaram 4+ anos para descobrir seu hedgehog. | I74: Palavras inglesas soltas no meio da frase, restos de tradução: 'companies' (730), 'rituals' (841), 'recipient' (957), 'wasted' (1010), 'governments' (1028), 'Conflicts' (1255). | J74: Reescrever: "Collins descreve empresas que levaram mais de quatro anos para achar o seu conceito do ouriço." Buscar e traduzir os demais. | K74: sim | L74: 7 | M74: não | Q74: Revisor de trecho | R74: Corrigido
A75: 74 | B75: 1 | C75: 736 | D75: FASE 0 | E75: C2 | F75: Informação possivelmente desatualizada | G75: média | H75: Walgreens (exemplo de Collins): | I75: Exemplo sem ressalva em 2026: a Walgreens encolheu e saiu da bolsa em 2025, comprada por um fundo. E os 15x de Collins cobrem 1975 a 2000, não 'por 15 anos' como diz a linha 741. | J75: Verificar e acrescentar uma frase: a Walgreens que Collins estudou perdeu o rumo duas décadas depois, lembrete de que o foco precisa ser revisto. Corrigir o período. | K75: não | L75: 1 | M75: sim | N75: desatualizado | O75: A Walgreens Boots Alliance foi comprada pela Sycamore Partners e saiu da Nasdaq em agosto de 2025, como empresa de capital fechado. O exemplo de Collins pede essa ressalva. | P75: https://www.sec.gov/Archives/edgar/data/1618921/000119312525190603/d87240dex991.htm | Q75: Revisor de trecho | R75: Corrigido
A76: 75 | B76: 1 | C76: 743 | D76: FASE 0 | E76: N3 | F76: Arquétipo inconsistente, decorativo ou ausente | G76: média | H76: Startup brasileira (aplicando): | I76: Onde a bíblia faria diferença, o manual usa empresa hipotética (Hedgehog), squad da Loggi (Team Canvas) e Série A (template). E o 'exemplo brasileiro' prometido (704) falta em vários frameworks. | J76: Preencher o Hedgehog com Lucas e Marina, o Team Canvas com Rafael e Bia antes do acordo de sócios e o template de advisor com Camila decidindo se pede demissão. | K76: sim | L76: 4 | M76: não | Q76: Revisor de trecho | R76: Corrigido
A77: 76 | B77: 1 | C77: 756 | D77: FASE 0 | E77: C5 | F77: Contradição interna | G77: alta | H77: Muito early: hedgehog emerge com tempo e iteração, Em organizações sem estabilidade para perseguir por 5+ anos. | I77: A ferramenta manda ficar na gaveta quando é cedo demais, e o livro a põe na Fase 0, antes da ideia. A lista virou vírgulas com 'Em' maiúsculo, falha repetida em 850, 1014 e 1072. | J77: Levar o Hedgehog para a Fase 2 ou 3, ou adaptá-lo à pessoa: "em que você pode ser muito bom, o que paga as suas contas e o que você ama". Refazer essas listas como itens. | K77: não | L77: 1 | M77: não | Q77: Revisor de trecho | R77: Corrigido
A78: 77 | B78: 1 | C78: 785 | D78: FASE 0 | E78: C3 | F78: Erro factual provável | G78: alta | H78: Fundadores seriais brasileiros. Quando David Vélez criou o Nubank | I78: Vélez é colombiano e o Nubank foi sua primeira empresa. Kalim também não era fundador serial. O pensamento entre aspas é atribuído a Vélez sem fonte, e o Nubank nasceu com aporte de fundos. | J78: Trocar o rótulo por "Como fundadores experientes aplicam" e usar fato verificável, sem monólogo inventado. Ou escolher um caso de fato efetual, de quem começou com o que tinha à mão. | K78: não | L78: 1 | M78: sim | N78: erro confirmado | O78: David Vélez é colombiano e vinha de fundos de investimento (General Atlantic e Sequoia), sem empresa própria registrada antes do Nubank. O Nubank começou com cerca de US$ 2 milhões de Sequoia e Kaszek. | P78: https://forbes.com.br/forbes-money/2021/07/como-david-velez-enfrentou-os-gigantes-do-setor-bancario-brasileiro-e-criou-o-banco-digital-mais-valioso-do-mundo/ | Q78: Revisor de trecho | R78: Corrigido
A79: 78 | B79: 1 | C79: 801 | D79: FASE 0 | E79: S5 | F79: Duplicação com outro capítulo ou volume | G79: média | H79: #### Framework: First Principles Thinking (Aristóteles, ~350 a.C.; popularizado por Elon Musk, anos 2010) | I79: Ferramentas copiadas em outros volumes: First Principles (v02), Cynefin, Red Team e Pre-mortem (v03), Valor Esperado (v03, v08), Pre-mortem (v09), Team Canvas (v06, v07), template de advisor (v02). | J79: Manter cada ferramenta inteira em um só volume e, nos outros, um parágrafo com o uso específico da fase e a remissão. | K79: sim | L79: 10 | M79: não | Q79: Revisor de trecho | R79: Corrigido
A80: 79 | B80: 1 | C80: 805 | D80: FASE 0 | E80: E9 | F80: Erro gramatical ou frase corrompida | G80: alta | H80: que definia "primeiros princípios" como "o primeiro basis from which a thing is known" | I80: Citação de Aristóteles meio traduzida, com português e inglês misturados, justo na seção sobre a origem do método. | J80: Reescrever: 'que definia primeiro princípio como "o primeiro ponto a partir do qual algo é conhecido" (Metafísica, livro V)'. Conferir o livro indicado na bibliografia, que diz livro IV (854). | K80: não | L80: 1 | M80: não | Q80: Revisor de trecho | R80: Corrigido
A81: 80 | B81: 1 | C81: 930 | D81: FASE 0 | E81: C1 | F81: Dado sem fonte ou precisão inventada | G81: média | H81: 90% das startups falham — mas todo fundador tem razões para acreditar que a sua é a exceção. | I81: O trecho que ensina a buscar a taxa-base usa uma taxa-base sem fonte, e 'falhar' muda de sentido conforme o estudo. | J81: Citar fonte e recorte (por exemplo, sobrevivência de empresas em cinco anos segundo IBGE ou Sebrae) ou escrever "a maioria das startups não chega a dar retorno". | K81: não | L81: 1 | M81: sim | Q81: Revisor de trecho | R81: Corrigido
A82: 81 | B82: 1 | C82: 934 | D82: FASE 0 | E82: E9 | F82: Erro gramatical ou frase corrompida | G82: média | H82: Não é possível eliminar vieses cognitivos — são fiados em arquitetura neural. | I82: A palavra 'fiados' está trocada (talvez de 'hardwired'). Na mesma linha, remissões aninhadas como '(Framework: Pre-mortem (Gary Klein, 2007) (Fase 0))' parecem saída de script. | J82: Reescrever: "Não dá para eliminar vieses: eles fazem parte de como o cérebro funciona. Dá para criar processos que os atenuem, como o pre-mortem e o red team desta fase." | K82: não | L82: 1 | M82: não | Q82: Revisor de trecho | R82: Corrigido
A83: 82 | B83: 1 | C83: 977 | D83: FASE 0 | E83: C5 | F83: Contradição interna | G83: média | H83: Passo 1, Após plano existir. Fazer pre-mortem antes de existir plano gera lista teórica sem tração. | I83: Contradiz a linha 681, que indica o pre-mortem antes da decisão de empreender. Na Fase 0 ainda não há plano de negócio, então a regra do manual veta o uso que a fase propõe. | J83: Adaptar: "Na Fase 0, o plano é a sua decisão de vida (sair do emprego em março, viver da reserva por 12 meses). Faça o pre-mortem desse plano." | K83: não | L83: 1 | M83: não | Q83: Revisor de trecho | R83: Corrigido
A84: 83 | B84: 1 | C84: 991 | D84: FASE 0 | E84: S6 | F84: Seção desproporcional ou fora de lugar | G84: alta | H84: Pre-mortem antes de iniciar expansão para México: | I84: O manual da Fase 0 foi escrito para empresa com time: SDRs e AEs (823), M&A (893, 1058), expansão ao México, pivô com ARR (1136), Série A (1377). O leitor ainda decide se empreende. | J84: Reescrever os exemplos para a decisão pessoal: pre-mortem de "larguei o emprego e deu errado em 18 meses", valor esperado de ficar na CLT ou empreender, red team com cônjuge e advisor. Usar as crenças da linha 675. | K84: sim | L84: 7 | M84: não | Q84: Revisor de trecho | R84: Corrigido
A85: 84 | B85: 1 | C85: 1105 | D85: FASE 0 | E85: E9 | F85: Erro gramatical ou frase corrompida | G85: média | H85: EV = (0.4 × 5M) + (0.4 × 1M) + (0.2 × 0) = R$ 2.4M. | I85: Decimais com ponto e 'M' à inglesa (12 casos no trecho). Para o leitor brasileiro, 'R$ 2.4M' se lê errado, e a linha 649 usa vírgula. | J85: Reescrever: "VE = (0,4 × 5) + (0,4 × 1) + (0,2 × 0) = R$ 2,4 milhões". Traduzir EV por VE (valor esperado) em todo o bloco. | K85: sim | L85: 12 | M85: não | Q85: Revisor de trecho | R85: Corrigido
A86: 85 | B86: 1 | C86: 1160 | D86: FASE 0 | E86: E9 | F86: Erro gramatical ou frase corrompida | G86: alta | H86: jogar russos roleta com EV positivo mas 17% de morte não é decisão racional | I86: Frase corrompida: 'russos roleta' no lugar de 'roleta-russa'. | J86: Reescrever: "(jogar roleta-russa com valor esperado positivo e 17% de chance de morrer não é decisão racional)". | K86: não | L86: 1 | M86: não | Q86: Revisor de trecho | R86: Corrigido
...

Sheet Checagem
A1: ID | B1: Volume | C1: Linha | D1: Trecho citado | E1: Desconfiança do revisor | F1: Veredito | G1: O que vale em out/2026 | H1: Fonte | I1: Nota para a correção
A2: r1-caso-045 | B2: 1 | C2: 448 | D2: O terceiro perfil é o especialista de domínio, ou hipster. | E2: Na tríade conhecida hacker, hustler e hipster, o hipster é o designer. O texto redefine o termo e depois cria o design como quarto perfil. Quem conhece a tríade desconfia do resto. | F2: não checada | G2: Não checada nesta rodada. | I2: Sem busca, por limite de esforço. O revisor aponta que, na tríade hacker, hustler e hipster, o hipster é o designer. Conferir antes de corrigir.
A3: r1-juri-023 | B3: 1 | C3: 736 | D3: Walgreens (exemplo de Collins): | E3: Exemplo sem ressalva em 2026: a Walgreens encolheu e saiu da bolsa em 2025, comprada por um fundo. E os 15x de Collins cobrem 1975 a 2000, não 'por 15 anos' como diz a linha 741. | F3: desatualizado | G3: A Walgreens Boots Alliance foi comprada pela Sycamore Partners e saiu da Nasdaq em agosto de 2025, como empresa de capital fechado. O exemplo de Collins pede essa ressalva. | H3: https://www.sec.gov/Archives/edgar/data/1618921/000119312525190603/d87240dex991.htm | I3: O período dos 15x de Collins (1975 a 2000, segundo o revisor) não foi conferido em fonte aberta. Revisar 'por 15 anos' na L741.
A4: r1-caso-001 | B4: 1 | C4: 785 | D4: Fundadores seriais brasileiros. Quando David Vélez criou o Nubank | E4: Vélez é colombiano e o Nubank foi sua primeira empresa. Kalim também não era fundador serial. O pensamento entre aspas é atribuído a Vélez sem fonte, e o Nubank nasceu com aporte de fundos. | F4: erro confirmado | G4: David Vélez é colombiano e vinha de fundos de investimento (General Atlantic e Sequoia), sem empresa própria registrada antes do Nubank. O Nubank começou com cerca de US$ 2 milhões de Sequoia e Kaszek. | H4: https://forbes.com.br/forbes-money/2021/07/como-david-velez-enfrentou-os-gigantes-do-setor-bancario-brasileiro-e-criou-o-banco-digital-mais-valioso-do-mundo/ | I4: O monólogo entre aspas não tem fonte e o rótulo 'fundadores seriais brasileiros' não cabe. Kalim (C6) não foi conferido. Usar fato verificável, sem fala inventada.
A5: r1-fina-043 | B5: 1 | C5: 1537 | D5: *Jobs to Be Done*, de Anthony Ulwick e Clayton Christensen | E5: Não existe livro com esse título escrito pelos dois. Ulwick publicou 'Jobs to be Done: Theory to Practice' (2016) e Christensen 'Competing Against Luck' (2016), de escolas rivais. | F5: erro confirmado | G5: São dois livros: 'Jobs to be Done: Theory to Practice', de Anthony Ulwick (2016), e 'Competing Against Luck', de Clayton Christensen, Taddy Hall e Karen Dillon (2016). | H5: https://www.goodreads.com/book/show/32809558 | I5: Citar as duas obras separadas e dizer em uma linha que divergem. Dados do livro de Christensen conferidos na Porchlight Books.
A6: r1-fina-001 | B6: 1 | C6: 1794 | D6: Wellhub (anteriormente Gympass) não começou pensando "academias para empresas". Começou pelo departamento de RH de empresa grande | E6: Provável erro: o Gympass nasceu vendendo diárias avulsas ao consumidor e depois migrou para o benefício corporativo. E a frase se contradiz: RH pagando academia é "academias para empresas". | F6: erro confirmado | G6: O Gympass, fundado em 2012, começou vendendo ao consumidor final (B2C). Depois de conflitos de repasse com as academias, reestruturou o modelo para venda direta a empresas. | H6: https://neofeed.com.br/videos/vida-de-startup/por-que-as-academias-quase-faliram-o-gympass | I6: Segundo o cofundador João Barbosa, a empresa mudou de modelo quatro vezes. Contar o RH como cunha achada no caminho, não como ponto de partida.
A7: r1-caso-002 | B7: 1 | C7: 2317 | D7: Clark, K. & Vesterlund, L. (2013). "Decision by default". Research sobre como inversion reduz viés. | E7: Referência com cara de inventada: não há trabalho conhecido de Clark e Vesterlund com esse título sobre inversão. Bibliografia falsa basta para desacreditar o livro. | F7: não verificável | G7: Não achei trabalho de Clark e Vesterlund chamado 'Decision by default'. Lise Vesterlund pesquisa doações e diferenças de gênero, não inversão. | H7: https://en.wikipedia.org/wiki/Lise_Vesterlund | I7: Duas buscas sem rastro da obra. Forte sinal de referência inventada. Cortar ou trocar pelas fontes que o revisor sugere (Munger e o pre-mortem de Klein).
A8: r1-fina-044 | B8: 1 | C8: 2575 | D8: | Aluguel da máquina | R$ 50-100/mês | R$ 0 (subsidiado) | Reduce | | E8: Tabela da Stone em 2014 com sinais de invenção: aluguel zero, capilaridade baixa por "foco digital" (a Stone apostou em polos locais), "Stone Box", "Ponto-de-Atenção", "Stone Hub" como software. | F8: erro confirmado | G8: O F-1 da StoneCo (2018) lista receita de assinatura e aluguel de equipamentos, 13,7% da receita de 2017 somados. Não há fonte para aluguel zero em 2014. | H8: https://www.sec.gov/Archives/edgar/data/1745431/000119312518289511/d580263df1.htm | I8: O dado é de 2017, não de 2014. 'Stone Box', 'Ponto-de-Atenção' e 'Stone Hub' não foram conferidos. Sem fonte, tirar os números e manter fatores qualitativos.
A9: r1-fina-002 | B9: 1 | C9: 3347 | D9: No lado restaurante, estabelecimentos com ticket de R$ 30 a R$ 80 sem operação de entrega estruturada. | E9: Anacronismo provável: em 2011 o iFood listava restaurantes que já entregavam com motoboy próprio. A logística própria veio anos depois, o que derruba também 3349 ('custo do motoboy'). | F9: erro confirmado | G9: Em 2011 o iFood atendia só restaurantes que já tinham delivery próprio. A empresa passou a fazer entregas a partir de 2015, porque muitos restaurantes não tinham entregadores. | H9: https://tecnoblog.net/especiais/ifood-domina-o-delivery-no-brasil-mas-restaurantes-e-rivais-contam-como-vao-reagir/ | I9: O lado restaurante em 2011 eram casas com motoboy próprio que perdiam pedidos no telefone. Ajustar também a L3349 sobre o custo do motoboy.
A10: r1-fina-045 | B10: 1 | C10: 4115 | D10: 1 squad (5 pessoas) por 6 meses para MVP + 4 meses de aquisição inicial = ~R$ 1.5M. Reavaliar em 10 meses: se GMV mensal não chegar a R$ 2M ou 5k microcreators ativos, descontinuar. | E10: Orçamento e critério de corte atribuídos à Hotmart sem fonte. O Sparkle conhecido é um app de comunidades, não um checkout simplificado. Parece caso inventado com nome real. | F10: erro confirmado | G10: O Sparkle da Hotmart é app de comunidades com assinaturas, lançado por volta de 2020, não um checkout simplificado para microcreators em 2022. Orçamento e critério de corte não têm fonte. | H10: https://tecnoblog.net/responde/o-que-e-o-sparkle-a-volta-das-comunidades/ | I10: Declarar 'caso hipotético inspirado na Hotmart', sem nome real de produto e sem números, ou usar uma aposta documentada.
A11: r1-juri-024 | B11: 1 | C11: 4553 | D11: Howard Marks, co-fundador da Oaktree Capital (US$ 180B AUM), cunhou o termo no livro *The Most Important Thing* (2011) | E11: Marks fala em 'second-level thinking' e não cunhou a ideia de efeitos de segunda ordem, que vem de Bastiat e Hazlitt. O AUM de US$ 180B precisa de data e checagem. | F11: desatualizado | G11: A Oaktree informa US$ 227 bilhões sob gestão em 30 de junho de 2026, não US$ 180 bilhões. | H11: https://s206.q4cdn.com/629311627/files/doc_financials/2026/q3/OCSL-3Q2026-Investor-Presentation_vF.pdf | I11: Não conferido aqui: o livro de Marks usa 'second-level thinking'. Preferir 'popularizou' a 'cunhou', como sugere o revisor.
A12: r1-trib-001 | B12: 1 | C12: 5515 | D12: o fundador que se remunera via empresa tem opções entre pro-labore (incide INSS) e dividendos (isentos se houver lucro) | E12: Desatualizado. A Lei 15.270/2025 criou, a partir de 2026, retenção de 10% sobre dividendos acima de R$ 50 mil por mês da mesma empresa e imposto mínimo para renda anual acima de R$ 600 mil. | F12: desatualizado | G12: Desde janeiro de 2026, dividendos pagos por uma mesma empresa a uma mesma pessoa física acima de R$ 50 mil no mês sofrem retenção de 10% sobre o valor total (Lei 15.270/2025). Renda anual acima de R$ 600 mil entra no imposto mínimo, de 0% a 10% conforme a faixa, a partir da declaração de 2027. | H12: https://www.planalto.gov.br/ccivil_03/_ato2023-2026/2025/lei/L15270.htm | I12: Lucros apurados até 2025, com distribuição aprovada até 31/12/2025 e pagos nos termos do ato, ficam fora da retenção. A alíquota mínima chega a 10% em R$ 1,2 milhão por ano.
A13: r1-trib-002 | B13: 1 | C13: 5519 | D13: E nunca pegar empréstimo pessoal para a empresa em nome próprio, exceto via contrato formal de mútuo com juros de mercado. Caso contrário, vira distribuição de lucro disfarçada com problemas tributários. | E13: Conceito trocado. Dinheiro do sócio que entra sem contrato arrisca ser tratado como suprimento de caixa sem origem (omissão de receita), não como distribuição disfarçada. Juros não são exigidos. | F13: erro confirmado | G13: Dinheiro do sócio que entra na empresa sem prova da entrega e da origem pode ser tratado como receita omitida (Decreto-Lei 1.598/1977, art. 12, § 3º). O risco não é distribuição disfarçada de lucro. | H13: https://www.planalto.gov.br/ccivil_03/decreto-lei/del1598.htm | I13: Contrato de mútuo e prova da origem na declaração do sócio afastam a presunção. Mútuo com mutuante pessoa física não sofre IOF (Decreto 6.306/2007, art. 5º, III).
A14: r1-trib-003 | B14: 1 | C14: 5523 | D14: Bradesco Prime, Itaú Personnalité, BB Estilo, Santander Select, com entrada tipicamente em duzentos a quinhentos mil em investimentos na instituição | E14: São segmentos de alta renda do varejo, não private banking, que começa muito acima. A mesma frase dá dois pisos diferentes: R$ 500 mil a 1 milhão e R$ 200 mil a 500 mil. | F14: parcialmente certo | G14: Prime, Personnalité, Estilo e Select são segmentos de alta renda do varejo, não private banking. O Itaú Personnalité aceita renda a partir de R$ 15 mil ou investimentos a partir de R$ 250 mil. | H14: https://www.itau.com.br/abrir-conta/personnalite | I14: O piso de investimento cabe na faixa do livro, mas o trecho chama os segmentos de private e fala em PL de R$ 500 mil a 1 milhão. Pisos mudam, mande o leitor conferir no banco.
... A19: r1-juri-002 | B19: 1 | C19: 6386 | D19: Contabilizei. SaaS de contabilidade online, Curitiba. Outro exemplo de crescimento disciplinado, fora do eixo SP-RJ. | E19: Contabilizei e Conta Azul (6388) são empresas conhecidas por ter captado venture capital cedo. Na lista de bootstrap, desacreditam o argumento. | F19: erro confirmado | G19: A Contabilizei foi fundada em 2013, recebeu aporte da Curitiba Angels em 2014 e da Kaszek em junho de 2015. Não é caso de bootstrap. | H19: https://www.baguete.com.br/noticias/contabilizei-recebe-aporte-da-kaszek | I19: Conta Azul (L6388) não foi checada. Se a Contabilizei ficar no livro, mover para 'captação disciplinada', com rodadas e datas.
A20: r1-juri-014 | B20: 1 | C20: 6541 | D20: **Kim Kubo (The.Care).** Cofundadora de healthtech. | E20: Pessoa e empresa não identificáveis e sem nenhum dado (ano, cidade, número). Se não existir, é caso inventado no capítulo sobre diversidade. | F20: não verificável | G20: Nenhuma fonte pública liga uma Kim Kubo a uma healthtech brasileira chamada The.Care. | I20: A busca só trouxe empresas sem relação, como a Kubo Care, da Índia. Apagar o parágrafo, como sugere o revisor.
A21: r1-juri-015 | B21: 1 | C21: 6546 | D21: Marcia Jordão (Accelera). Andrea Bisker (Pacífica Holding). Karen Habib (SERASA Experian). Marina Proença (Solides). Eli Guinther (cofundadora Orion). | E21: Pares nome e empresa não verificáveis. A cofundadora e CEO conhecida da Solides é Mônica Hauck. 'Women in Tech BR' também é vago. Parece lista gerada sem checagem. | F21: erro confirmado | G21: A Sólides foi fundada em 2010 por Mônica Hauck e Alessandro Garcia. Marina Proença não aparece como fundadora. | H21: https://diariodocomercio.com.br/negocios/rh-fundamental-crescimento-pmes-diz-co-ceo-solides/ | I21: Os demais pares nome e empresa não foram checados. Refazer o quadro só com nomes conferidos, com empresa, cidade e fonte, ou apagá-lo.
A22: r1-fina-004 | B22: 1 | C22: 6587 | D22: Empresas híbridas entre for-profit, e impacto (Outbound, VU Brasil, Instituto Trata Brasil em forma empresarial, Gerando Falcões ecosystem). | E22: Trata Brasil é OSCIP e Gerando Falcões é ONG, não empresas híbridas. 'Outbound' e 'VU Brasil' não são identificáveis. 'Framework de Theory of Change, descrever' tem sintaxe quebrada. | F22: erro confirmado | G22: O Instituto Trata Brasil é OSCIP, entidade sem fins lucrativos formada por empresas interessadas no saneamento, e não empresa híbrida. | H22: https://tratabrasil.org.br/wp-content/uploads/2024/03/Codigo-de-Conduta_aprovado.pdf | I22: Gerando Falcões, Outbound e VU Brasil não foram conferidos. Citar só empresas de impacto verificadas e explicar teoria da mudança em uma frase.
A23: r1-fina-005 | B23: 1 | C23: 6589 | D23: Ambipar (gestão ambiental) construiu negócio em torno de serviço ambiental a outras empresas. | E23: A Ambipar entrou em recuperação judicial em 2025, segundo o noticiário econômico. Citá-la como sucesso ESG em 2026 é dado vencido. 'O líder vegetal Fazenda Futuro' é frase truncada. | F23: desatualizado | G23: A Ambipar teve o processamento da recuperação judicial deferido em 30/10/2025 pela Justiça do Rio de Janeiro, com dívidas declaradas de R$ 10,48 bilhões. | H23: https://mercadoeconsumo.com.br/31/10/2025/economia/justica-defere-pedido-de-recuperacao-judicial-da-ambipar/ | I23: Tirar como caso de sucesso ESG ou usar como alerta sobre alavancagem. Status atual da Fazenda Futuro não conferido.
A24: r1-caso-003 | B24: 1 | C24: 7071 | D24: só ocorre em narrativa, não em apresentação de dados | E24: Exagera o estudo de Stephens, Silbert e Hasson (2010), que comparou uma história compreendida com uma incompreensível, não com dados. O mapa de áreas cerebrais é de divulgação, sem fonte. | F24: erro confirmado | G24: Stephens, Silbert e Hasson (PNAS, 2010) usaram só uma história real contada em inglês. O acoplamento entre cérebros sumiu quando o ouvinte não entendia (história em russo), e o estudo não comparou narrativa com dados. | H24: https://pmc.ncbi.nlm.nih.gov/articles/PMC2922522/ | I24: O mapa de áreas ativadas por história contra dados também não vem desse estudo. Usar a redação do revisor: a atividade do ouvinte acompanha a do narrador quando ele entende.
A25: r1-caso-004 | B25: 1 | C25: 8071 | D25: Este capítulo reflete o estado da IA generativa em abril de 2026 e deve ser revisitado todo ano. | E25: A data não se sustenta: o capítulo cita GPT-4 Turbo (8110), Galileo AI e v0.dev (8152, 8242) e "ChatGPT Data Analysis" (8240), e o Cap. 11 (8284) diz que ele traz práticas de 2023 "hoje obsoletas". | F25: desatualizado | G25: Em outubro de 2026 várias ferramentas do capítulo envelheceram. O GPT-4 Turbo, citado na linha 8110, teve o fim anunciado em 22/04/2026 e sai da API da OpenAI em 23/10/2026. | H25: https://developers.openai.com/api/docs/deprecations | I25: Galileo AI, v0.dev e 'ChatGPT Data Analysis' não foram conferidos. Datar a nota só depois de checar cada ferramenta, ou fundir com o Cap. 11.
A26: r1-caso-005 | B26: 1 | C26: 8110 | D26: (Claude, ou GPT-4 Turbo) | E26: GPT-4 Turbo é de 2023 e foi substituído em 2024 e 2025. Num capítulo datado de 2026, o nome denuncia texto velho. | F26: desatualizado | G26: O GPT-4 Turbo teve o fim anunciado em 22/04/2026 e sai da API da OpenAI em 23/10/2026. Não serve como exemplo atual de modelo de contexto longo. | H26: https://developers.openai.com/api/docs/deprecations | I26: Usar a formulação do revisor: um assistente com contexto longo (Claude, ChatGPT ou Gemini, na versão atual).
A27: r1-juri-026 | B27: 1 | C27: 8311 | D27: Em 2026, padrão é ter IA participando de toda reunião importante. Gerando ata, e extraindo compromissos. | E27: Sem ressalva: gravar cliente, candidato ou investidor exige aviso e base legal (LGPD) e pode violar NDA. Idem a triagem de CV por IA (8326), que a LGPD (art. 20) e o PL 2338 tratam como risco. | F27: parcialmente certo | G27: Gravar e transcrever reunião é tratamento de dado pessoal e pede base legal e transparência (LGPD). O PL 2338/2023 segue aguardando parecer na comissão especial da Câmara, sem votação em outubro de 2026. | H27: https://dadosabertos.camara.leg.br/api/v2/proposicoes/2487262 | I27: Acrescentar aviso e consentimento antes de pôr robô na reunião. Na triagem de CV (L8326), a decisão é humana e o candidato pode pedir revisão (LGPD, art. 20).
A28: r1-fina-006 | B28: 1 | C28: 8420 | D28: Finep e BNDES Garagem oferecem capital de fomento público, em geral por empréstimo e não por equity, com taxas abaixo de mercado. | E28: BNDES Garagem é programa de aceleração, não crédito. A Finep também dá subvenção não reembolsável e investe em participação. "BNDES Social Bond" parece título de dívida, não programa para startup. | F28: erro confirmado | G28: O BNDES Garagem é programa de aceleração gratuito, sem crédito e sem exigir participação, com prêmios em dinheiro aos finalistas. A Finep opera crédito e também repassa subvenção do FNDCT, como no Centelha. | H28: https://garagem.bndes.gov.br/wp-content/uploads/2025/08/Edital-Negocios-de-Impacto-2025-TRACAO-Ciclo-2-_-BNDES-Garagem.pdf | I28: Garagem ativo, com ciclo 2025-2026 e Demoday em 16/6/2026. Investimento em participação pela Finep e o 'BNDES Social Bond' não foram conferidos.
A29: r1-caso-006 | B29: 1 | C29: 8422 | D29: O ticket em 2025 e 2026 é de quinhentos mil dólares (cerca de dois milhões e meio de reais) em troca de sete por cento de equity. | E29: No acordo padrão do YC, os 7% compram US$ 125 mil. Os outros US$ 375 mil entram em SAFE sem teto, que converte na rodada seguinte. Erro repetido em 8430. "Ou remota" também envelheceu. | F29: erro confirmado | G29: O YC investe US$ 500 mil: US$ 125 mil em SAFE post-money por 7% e US$ 375 mil em SAFE sem teto com cláusula de nação mais favorecida (MFN). | H29: https://www.ycombinator.com/deal | I29: Mesmo erro na linha 8430. O YC descreve programa de três meses, quatro turmas por ano, kickoff presencial e encontros semanais em San Francisco. Rever 'ou remota'.
A30: r1-fina-007 | B30: 2 | C30: 204 | D30: Hoje a empresa vale mais de US$ 14 bilhões e é peça essencial para OpenAI, Meta, e o Pentágono. | E30: Desatualizado: em 2025 a Meta comprou 49% da Scale AI (avaliação perto de US$ 29 bi), Wang foi para a Meta e OpenAI e Google reduziram o uso. A frase sobre Wang citar Graham pede fonte. | F30: desatualizado | G30: Em junho de 2025 a Meta investiu cerca de US$ 14,3 bilhões por 49% da Scale AI, avaliada em US$ 29 bilhões. Alexandr Wang deixou o cargo de CEO e foi para a Meta. | H30: https://techcrunch.com/2025/06/13/scale-ai-confirms-significant-investment-from-meta-says-ceo-alexandr-wang-is-leaving/ | I30: Os US$ 14 bi do livro batem com a avaliação de 2024 (US$ 13,8 bi). Redução de uso por OpenAI e Google não confirmada nesta fonte. Citação de Wang não conferida.
A31: r1-caso-007 | B31: 2 | C31: 287 | D31: ##### As cinco perguntas canônicas do Mom Test (cheat sheet) | E31: As cinco perguntas (parte mais difícil, última vez, por que foi difícil, o que já fez, o que não gosta nas soluções) são do "How to Talk to Users" de Eric Migicovsky (YC), não do livro de Fitzpatrick. | F31: erro confirmado | G31: As cinco perguntas (parte mais difícil, última vez, por que foi difícil, o que já fez, o que não gosta nas soluções) são da palestra 'How to Talk to Users', de Eric Migicovsky, da Y Combinator. | H31: https://www.indiehackers.com/post/eric-migicovsky-how-to-talk-to-users-summary-e3c4c844cc | I31: Fonte é resumo que remete ao vídeo da YC Library, cuja página não abriu. Atribuir a Migicovsky e dizer que as perguntas são compatíveis com o Mom Test.
A32: r1-juri-003 | B32: 2 | C32: 2849 | D32: Em vez de "otimizar o processo de aluguel", posicionaram como "aluguel sem fiador, sem vistoria, sem caução". | E32: O QuintoAndar faz vistoria de entrada e saída. A promessa pública era sem fiador e sem caução. A "pesquisa qualitativa extensa" de 2013 e a dor "social, não financeira" não têm fonte. | F32: parcialmente certo | G32: A promessa oficial do QuintoAndar é aluguel 'sem fiador, sem caução' e com contrato eletrônico. 'Sem vistoria' não faz parte dela. | H32: https://www.quintoandar.com.br/newsroom/sobre/ | I32: O site recruta vistoriadores, sinal de que há vistoria. A pesquisa qualitativa de 2013 e a dor 'social' não têm fonte pública achada. Tratar como reconstrução.
... A46: r1-juri-005 | B46: 3 | C46: 3386 | D46: A PlayKids, fundada em 2013 por Eric Acher, Marcelo Roque e Gabriel Borges em São Paulo (parte do grupo Movile) | E46: Eric Acher é conhecido como cofundador da gestora Monashees, não da PlayKids, que nasceu dentro da Movile. Os outros nomes e os cem milhões de downloads também pedem checagem. | F46: erro confirmado | G46: A PlayKids foi lançada pela Movile em junho de 2013. Nenhuma fonte a liga a Eric Acher, Marcelo Roque ou Gabriel Borges, e desde 2022 ela pertence à Sandbox & Co, com a Movile minoritária. | H46: https://techcrunch.com/2013/06/25/playkids-tv/ | I46: Em 2022 tinha 4 milhões de usuários mensais em 130 países (Bloomberg Línea). Os 100 milhões de downloads e 180 países não se confirmaram. Usar a versão sem nomes.
A47: r1-juri-018 | B47: 3 | C47: 4220 | D47: ##### Exemplo brasileiro preenchido — Wildlife Studios, MVP de novo mecanismo de monetização (2022) | E47: Coorte de 50 mil jogadores, ARPU de R$ 18 e conversão de 17% atribuídos à Wildlife sem fonte. Dados internos com cara de invenção, de empresa grande, num volume para fundador pré-MVP. | F47: não verificável | G47: Não há fonte pública para a coorte de 50 mil jogadores, o ARPU de R$ 18 e a conversão de 17% atribuídos à Wildlife Studios. | I47: Busca sem resultado. Rotular como ilustração ou trocar por um MVP Canvas do porte do leitor.
A48: r1-trib-007 | B48: 3 | C48: 4624 | D48: Com quinze a vinte respostas, plote as quatro curvas. A intersecção entre "caro" e "barato" indica a faixa de preço psicologicamente aceitável. | E48: No método, o cruzamento de "caro" com "barato" dá um ponto (preço de indiferença), não uma faixa. E 15 a 20 respostas geram curvas instáveis demais para traçar limites. | F48: erro confirmado | G48: No método de Van Westendorp, o cruzamento de 'barato' com 'caro' é o ponto de indiferença, um preço só. A faixa aceitável vai do cruzamento de 'barato demais' com 'não barato' ao de 'caro demais' com 'não caro'. | H48: https://rdrr.io/cran/pricesensitivitymeter/man/psm_analysis.html | I48: O ponto ótimo é o cruzamento de 'barato demais' com 'caro demais'. A fonte não fixa amostra mínima, mas 15 a 20 respostas devem ser tratadas como pista.
A49: r1-juri-006 | B49: 3 | C49: 4755 | D49: Em meados da década de 2010, a Gupy nascia da ideia de Mariana Dias, Bruna Guimarães, e Robinson Idalgo de substituir processos tradicionais de recrutamento | E49: Quadro de fundadores a conferir. As fontes que conheço citam Mariana Dias, Bruna Guimarães, Guilherme Dias e Robson Ventura (2015). "Robinson Idalgo" parece nome trocado. | F49: erro confirmado | G49: A Gupy foi fundada em 2015 por Mariana Dias, Bruna Guimarães, Guilherme Dias e Robson Ventura. 'Robinson Idalgo' não consta. | H49: https://forbes.com.br/forbes-tech/2022/01/os-proximos-passos-da-gupy-apos-meio-bilhao-em-aporte/ | I49: Trocar 'em meados da década de 2010' por 'em 2015' e corrigir os nomes.
A50: r1-caso-015 | B50: 3 | C50: 6036 | D50: Já uma startup de biotech pode estar em TRL 3, mesmo após cinco anos de operação. Se estiver em ensaios clínicos. | E50: Na escala biomédica usada por agências americanas (HHS e DoD), ensaio clínico corresponde a TRL 6 a 8. Quem está em ensaio clínico não está em TRL 3. E a frase foi partida ao meio. | F50: erro confirmado | G50: Na escala biomédica do Departamento de Defesa dos EUA, TRL 3 é prova de conceito inicial em laboratório ou animal, TRL 6 é o ensaio clínico de fase 1 e TRL 7 cobre as fases 2 e 3. | H50: https://cdmrp.health.mil/jwmrp/pdfs/Biomedical%20Product%20Guidelines.pdf | I50: Quem está em ensaio clínico está em TRL 6 ou 7, não 3. Juntar a frase partida e usar a redação do revisor, com TRL 6 no primeiro ensaio clínico.
